Workbook

Sheet Indicaciones
A6: Reto | Construcción de VSM de un producto o familia de productos
A7: para un cliente de su empresa
B20: Nombre del participante
B21: Daniel Ignacio Michelena Mujica

Sheet VSM Actual
M2: Terreno Materia Almacen Primario de Materia Prima
K17: Area de Habilitado para produccion de armables en Planta Metalmecanica
C18: Area de descarga Materia Prima
L20: Takt | M20: 16 | N20: =+M20/M21 -> 0.47058824 | O20: Horas/toneladas
M21: 34
C22: Anden
L23: Pitch Time | M23: 16 | N23: =+M23/M24 -> 1.4545455 | O23: Horas/toneladas
C24: Alamcen Placas | F24: Almacen de Perfiles | M24: 11
C31: Usado Para Chatarra Actualmente
K36: Corte de Placa
L37: 2
K38: Maquina Thor Placa
K39: T. Disponible | L39: 16
K40: C/T | L40: 3
K41: C/O | L41: 0.5
K42: Up-Time | L42: 14
K43: Q/R | L43: =+(120-15)/120 -> 0.875
K44: Lote
D47: Corte de Placa | H47: Almacen de Partes
E48: 2
D49: Maquina Hight Speed
D50: T. Disponible | E50: 16
D51: C/T | E51: 3
D52: C/O | E52: 0.5
D53: Up-Time | E53: 12
D54: Q/R | E54: =+(260-5)/260 -> 0.98076923
D55: Lote
C60: Biselado de Placa
D61: 4
C62: Maquina semi atomaticas
C63: T. Disponible | D63: 16 | K63: Corte Perfil | U63: 1 Carro de distribucion de Perfiles
C64: C/T | D64: 1 | L64: 2 | O64: Alamacen de Partes | W64: Nave 3
C65: C/O | D65: 0.2 | K65: Maquina BDL | S65: Alamacen de perfiles
C66: Up-Time | D66: 12 | K66: T. Disponible | L66: 16
C67: Q/R | D67: =+(18-1)/18 -> 0.94444444 | K67: C/T | L67: 0.2
C68: Lote | K68: C/O | L68: 0.1
K69: Up-Time | L69: 14
K70: Q/R | L70: =+(123-14)/123 -> 0.88617886
K71: Lote
K74: Corte de Placa | O74: Area Formacion de Paquetes
...

Sheet VSM Futuro
V1: Biselado de Placa
M2: Terreno Materia Almacen Primario de Materia Prima | W2: 4
V3: Maquina Thor Placa
V4: T. Disponible | W4: 16
V5: C/T | W5: 1
V6: C/O | W6: 0.2
V7: Up-Time | W7: 12
V8: Q/R | W8: =+(18-1)/18 -> 0.94444444
V9: Lote
K17: Area de Habilitado para producción de armables en Planta Metalmecanica
C18: Area de descarga Materia Prima | L18: Los paquetes se forman de perfiles y placas
L20: Takt | M20: 16 | N20: =+M20/M21 -> 0.47058824 | O20: Horas/toneladas
M21: 34
C22: Anden
L23: Pitch Time | M23: 16 | N23: =+M23/M24 -> 1.4545455 | O23: Horas/toneladas
C24: Alamcen Placas | F24: Almacen de Perfiles | M24: 11
C31: Anden de Materia Prima
C32: solo para cubrir demanda de 4 lotes
K36: Corte de Placa
K38: Maquina Thor Placa
K39: T. Disponible | L39: 16
K40: C/T | L40: 3
K41: C/O | L41: 0.5
K42: Up-Time | L42: 14
K43: Q/R | L43: =+(120-15)/120 -> 0.875
K44: Lote
K47: Corte de Placa | O47: Almacen de Partes
L48: 2
K49: Maquina Hight Speed
K50: T. Disponible | L50: 16
K51: C/T | L51: 3
K52: C/O | L52: 0.5
K53: Up-Time | L53: 12
K54: Q/R | L54: =+(260-5)/260 -> 0.98076923
K55: Lote
U58: Bisel de Placa y perfil
V59: 8
U60: Equipos semiautomaticos
U61: T. Disponible | V61: 16
U62: C/T | V62: 1
...

Sheet VSM Habilitado Actual
I4: Planta Metalmecanica Metalitec
B10: 40 ton/semana Perfiles y Placas
B12: Terreno de acopio | AB12: 24 colum/dia
P13: Primer Proyecto
D18: Carga Materia P | I18: Descarga Maateria P | N18: Corte Peddibot Perfil | T18: Corte y Biselado
J19: 1 | O19: 2 | U19: 4
D21: T. Disponible | E21: 420 | I21: T. Disponible | J21: =8*60-60 -> 420 | N21: T. Disponible | O21: =+U21 -> 1680 | T21: T. Disponible | U21: =2*14*60 -> 1680
D22: C/T | E22: 120 | I22: C/T | J22: =+'Hoja de Datos del proceso'!G25-120 -> 60 | N22: C/T | O22: =+'Hoja de Datos del proceso'!C35 -> 26 | T22: C/T | U22: =+'Hoja de Datos del proceso'!I35 -> 60
D23: C/O | E23: 60 | I23: C/O | J23: 120 | N23: C/O | O23: 5 | T23: C/O | U23: 15
D24: Up-Time | E24: 360 | I24: Up-Time | J24: 360 | N24: Up-Time | O24: =+O21-40 -> 1640 | T24: Up-Time | U24: =+U21-60 -> 1620
D25: Q/R | E25: 1 | I25: Q/R | J25: 1 | N25: Q/R | O25: =+'Hoja de Datos del proceso'!C40 -> 0.3556 | T25: Q/R | U25: =+'Hoja de Datos del proceso'!I40 -> 0.9444 | X25: 42 | Y25: piezas
D26: Lote | I26: Lote | N26: Lote | T26: Lote
D27: 1 Turno | I27: 1 Turno | N27: 2 turnos | T27: 2 turnos
L28: 21 perfiles | Q28: 17
V29: Cambiar de ubicación
B30: Descargar directo del Proveedor al Anden | V30: para que el flujo vaya
V31: no en contra flujo
N34: Reparar para bajar retrabajo | Q34: Bajar inventario | X34: Aumentar Carros de distribucion
K35: Bajar inventario | N35: y aumentar funciones
T36: Corte y Biselado
D37: Carga Materia P | I37: Descarga Maateria P | N37: Corte BDL Perfil | U37: 2
E38: 4 | J38: 1 | O38: 2
T39: T. Disponible | U39: 1680
D40: T. Disponible | E40: 420 | I40: T. Disponible | J40: 420 | N40: T. Disponible | O40: 1680 | T40: C/T | U40: =+'Hoja de Datos del proceso'!I35 -> 60
D41: C/T | E41: 120 | I41: C/T | J41: 60 | N41: C/T | O41: =+'Hoja de Datos del proceso'!G14 -> 28 | T41: C/O | U41: 15
D42: C/O | E42: 60 | I42: C/O | J42: 120 | N42: C/O | O42: 5 | T42: Up-Time | U42: 1620
D43: Up-Time | E43: 360 | I43: Up-Time | J43: =420-60 -> 360 | N43: Up-Time | O43: 1640 | T43: Q/R | U43: =+U25 -> 0.9444
B44: Descargar directo del pro | D44: Q/R | E44: 1 | I44: Q/R | J44: 1 | N44: Q/R | O44: =+'Hoja de Datos del proceso'!H48 -> 0.8862 | T44: Lote
B45: veedor al anden | D45: Lote | I45: Lote | N45: Lote | T45: 2 turnos
D46: 1 turno | I46: 1 turno | L46: 28 perfiles | N46: 2 turnos | Q46: 23 piezas
L53: Bajar inventario | Q53: Bajar inventario
I54: Carga Materia P | N54: Descarga Maateria P | T54: Hight Speed Placa
J55: 4 | O55: 1 | U55: 2
I57: T. Disponible | J57: 420 | N57: T. Disponible | O57: 420 | T57: T. Disponible | U57: 1680
I58: C/T | J58: 120 | N58: C/T | O58: 60 | T58: C/T | U58: =+'Hoja de Datos del proceso'!C51 -> 40
I59: C/O | J59: 60 | N59: C/O | O59: 120 | T59: C/O | U59: 25
I60: Up-Time | J60: 360 | N60: Up-Time | O60: 360 | T60: Up-Time | U60: 1620
I61: Q/R | J61: 1 | N61: Q/R | O61: 1 | T61: Q/R | U61: =+'Hoja de Datos del proceso'!C56 -> 0.9808
I62: Lote | N62: Lote | Q62: 20 placas | T62: Lote
I63: 1 Turno | N63: 1 Turno | T63: 2 turnos
...

Sheet Planta Metalitec Actual
E3: Retrazo en el procesamiento de la requisiciones por sistema | J3: Falta Coordinación con Plantas
H4: Error en Pedidio en Catidad y Tipo de Materiales | M4: Incertidumbre en Presupuestos
H5: Requisiciones | J5: Ingenieria | L5: Comercial | M5: no corresponden al costo real | R5: Demanda del Cliente
A6: Inventario Incompleto y no esta en Strumis | J6: Tekla
J7: Strumis | R7: 3 | S7: Lotes/semana
J8: Planos defectuosos Falta de inofrmacion y NC1 | R8: 1 | S8: Lote 40 ton
A9: Terreno en mal estado | B9: 8 | C9: Lotes | E9: Planificación y Control de Avance
H10: No hay control efectivo de avance | O10: Demasiado Inventario
R11: 6 | S11: Viajes por semana
H12: Falta de Personal | S12: (30 ton/viaje)
A13: Equipos dañados | O13: 23 | P13: Lotes
G14: Solicitud de Perfiles
J15: Retrabajos | L15: Retrabajos | N15: Perdida de Piezas
C16: Sala Tecnica | F16: Habilitado | I16: Armado | L16: Soldadura | P16: Pintura
K17: No hay datos
C19: T. Disponible | D19: 9 | F19: T. Disponible | G19: 18 | I19: T. Disponible | J19: 10 | L19: T. Disponible | M19: 10 | P19: T. Disponible | Q19: 10
B20: 8 lotes | C20: C/T | D20: 9 | F20: C/T | G20: 9 | I20: C/T | J20: 9 | L20: C/T | M20: 9 | P20: C/T | Q20: 9
C21: C/O | D21: 0 | F21: C/O | G21: 1 | I21: C/O | J21: 0 | L21: C/O | M21: 0 | P21: C/O | Q21: 0
C22: Up-Time | D22: -11 | F22: Up-Time | G22: 12 | I22: Up-Time | J22: 9 | L22: Up-Time | M22: 9 | P22: Up-Time | Q22: 9
C23: Q/R | D23: 0.98 | E23: 8 lotes | F23: Q/R | G23: 0.65 | H23: 8 lotes | I23: Q/R | J23: 0.8 | K23: 5 lotes | L23: Q/R | M23: 0.8 | N23: 3,5 lotes | P23: Q/R | Q23: 0.9
E26: Reducir Inventario | H26: Reducir Inventario
F27: Retrabajos por errores de maquinas y Operadores | J27: Errores de Armado | L27: Errores de Soldadura | P27: Perdida de HH por falta de marcas en Piezas
C28: Falta de Personal | F28: Falta de supervision y Control | J28: Falta de personal | L28: Falta de personal | P28: Pérdida de Piezas
C29: Falta de procesos | F29: No hay balance entre Placas y perfiles | J29: Faya en lectura de planos | L29: Faya en lectura de planos | P29: Daño de piezas por mal manejo
A30: Demasiado, Reducir Inventarios a 5 lotes | C30: Mal Aprovechamiento | F30: Perdida de Piezas y refabricacion | J30: Falta de Compromiso | L30: Falta de Compromiso
C31: Falta de Comunicación | F31: Falta de control de entregas | J31: Falta de Creatividad | L31: Falta de Creatividad | P31: Cambios contantes de prioridad de envio
C32: No se revisan los NC1 | F32: Entregas incompletas | J32: Desorden General | L32: Solo se usa FCAW y SMAW
C33: No se revisa las requisiciones vs aprovechamiento | F33: Falta permanente de Consumibles por no solicitarlos a tiempo | J33: Perdida de HH por Armables Incompletos | L33: Retrabajos por errores de Habilitado y Armado | P33: Desorden de envio de piezas auemnta consumo de HH en Clasificaion
F34: Suministro de datos erroneos a Strumis | J34: Retrabajos por errores de Habilitado | L34: Falta de equipos manuales basicos
C35: No verifica Inventario Vs Requerimiento | F35: Fabricacion repetida de Piezas | J35: Falta Supervision a Contratistas | L35: Soldaduras con Piezas Incompletas | P35: Perdida de Pintura por mala aplicación
C36: Falta de Programas para Nesting | F36: Falta de Control de uso de Materiales | J36: Falta de equipos manuales basicos | L36: Falta Supervision de Contratistas | P36: Perdida de HH por mal tiempo
C37: No piden perfiles y placas coordinado esto desbalancea la produccion de armables | F37: Equipos defectuosos | J37: Falta de Control de ubicación de piezas | L37: Falta de Control de ubicación de piezas | P37: Perdida de HH por equipos dañados
F38: Personal no comprometido | J38: Perdida de piezas y Partes | L38: Perdida de tiempo en marcado de Piezas
C39: Falta de Presencia segundo Turno | F39: Falta de Herramientas | J39: Excceso de HH de Control de Calidad | L39: Se hacen actividades de otro departamento
C40: Ruteo de piezas incompleto | F40: Mala Logistica por falta de equipos moviles | J40: Armado en no secuencia para completar lotes | L40: Excceso de HH de Control de Calidad
C41: Falta Coordinacion con Habilitado | F41: Mal flujo de Trabajo por erronea ubicación de estaciones de trabajo | L41: Perdida de HH por falta de piezas armadas
C42: No hay infomracion cuando hay cambios en Ingenieria | F42: Marcado erroneo en Partes
F43: Perdida de Tiempo en Marcaje no automatico
F44: Uso de procedimiento de Punta y Cola frena produccion y favorece a cometer errores
F45: Falta de Comunicación con Mantenimiento
...

Sheet VSM template
D4: Tiempo disponible | L4: Información | N4: Técnicas de | P4: Lluvia de ideas | R4: Horno | T4: Anuncio | V4: Kaizen | W4: Logo compañía | Z4: Compañía
D5: Demanda del cliente | J5: Operador | L5: telefónica | N5: ayuda visual | T5: en equipo
A6: T/T | B6: Tiempo de transportación | D6: U/T | E6: Uptime (tiempo de funcionamiento) | J6: Almacén ( W.I.P o | L6: P. entradas P. salidas | N6: Push | P6: Kanban de | R6: Camión | T6: Inventario | V6: MRP/ERP
A7: Q/T | B7: Tiempo de fila | D7: Q/R | E7: Tasa de calidad = (pzs.fab - pzs.defect)/pzs. Fab. | J7: prod. term. ) | L7: (flujo en secuencia ) | N7: (al siguiente proceso) | P7: Producción
A8: C/T | B8: Tiempo de ciclo | D8: T/M | E8: Tiempo muerto = Tiempo disponible - tiempo trabajado | J8: Push | L8: Kanban de Retiro | N8: Pull | P8: Kanban de señal | R8: Montacargas | T8: Buzón de Kanban | V8: Inventario de
A9: C/O | B9: Tiempo de preparación | D9: E/O | E9: Eficiencia operativa = Tiempo est. Unit/Tiempo ciclo | J9: (prod. terminado) | N9: (e.j. desde el almacén) | V9: seguridad/Buffer
A10: Tiempo de entrega = Tiempo de procesamiento + tiempo de fila | J10: Flujo de información | L10: Flujo de información | N10: Nivelación de carga | P10: Cliente o | R10: Vaya a ver | T10: Pelota de Pull | V10: Celda de | W10: Hecho por: | Y10: Coordinador | AA10: Fecha | AC10: Mapa No. | AD10: Rev. | AE10: Hoja
A11: Tiempo de procesamiento = Σ tiempo de ciclo de cada proceso | J11: Electrónico | L11: Manual | P11: Proveedor | T11: secuenciado | V11: manufactura | AD11: 0 | AE11: 1 of 1
E14: NVA
G15: Proceso
C16: VA
G18: T. Disponible
G19: C/T
G20: C/O
G21: Up-Time
G22: Q/R
G23: Lote

Sheet Hoja de Datos del proceso
A4: N° | B4: Descripcion | C4: Simbolos | G4: Datos
G5: Tiempo (Minutos) | H5: Cantidad (Unds) | I5: Distancia (metros) | J5: Superficie (Metros 2) | K5: Observaciones
A6: 1 | B6: Verificacion de Cantidades y Marcas en Placas en Paquete | C6: X | E6: X | G6: 10
A7: 2 | B7: Entrega de Perfiles BDL a Produccion | C7: X | G7: 10
A8: 3 | B8: Entrega de Perfiles Peddibot a Produccion | C8: X | G8: 10
A9: 4 | B9: Entrega de Paquetes de Placas a Produccion | C9: X | G9: 10
B10: Armado de Paquetes de placas | C10: X | G10: 40
B11: Stock de Placas | H11: 482 | J11: 400
A12: 5 | B12: Movimiento de Perfiles de BDL a area de Biselado | D12: X | G12: 10 | I12: 25
B13: Stock de Perfiles 1 | H13: 21 | J13: 90
A14: 6 | B14: Corte y barrenado de Perfiles en la BDL | C14: X | G14: 28
A15: 7 | B15: Alimentacion de Perfiles a BDL | C15: X | D15: X | G15: 25
A16: 8 | B16: Movimiento de Placa FBP a Area de Paquete | C16: X | D16: X | G16: 15 | I16: 10
A17: 9 | B17: Corte y Punzonado en FBP | C17: X | G17: 70
A18: 10 | B18: Alimetacion de placa a FBP | C18: X | D18: X | G18: 20
A19: 11 | B19: Movimiento de Perfiles Peddibot a area de Biselado | D19: X | G19: 10 | I19: 40
B20: Stock de Perfiles 2 | H20: 21 | J20: 60
A21: 12 | B21: Verificacion de corte Peddibot | C21: X | E21: X | G21: 65
A22: 13 | B22: Corte de Perfiles en Peddibot | C22: X | G22: 65
A23: 14 | B23: Alimentacion de Perfiles a Peddibot | C23: X | D23: X | G23: 30
B24: Verificacion de Control de Calidad de Materia Prima | E24: X | G24: 40
A25: 15 | B25: Carga, Movimiento y descarga de Almacen de Materia Prima a Habilitado Hight Speed | D25: X | F25: X | G25: 180 | I25: 400 | J25: 24
A26: 16 | B26: Carga, Movimiento y descarga de Almacen de Materia Prima a Habilitado a FBP | D26: X | F26: X | G26: 180 | I26: 400 | J26: 24
A27: 17 | B27: Carga, Movimiento y descarga de Almacen de Materia Prima a Habilitado Peddibot | D27: X | F27: X | G27: 180 | I27: 400 | J27: 42
A28: 18 | B28: Carga, Movimiento y descarga de Almacen de Materia Prima a Habilitado BDL | D28: X | F28: X | G28: 180 | I28: 400 | J28: 42
B29: Envio de Materia Prima del Proveedor | D29: X | I29: 150 Km
B32: Hoja de Datos de Procesos
B34: Corte Peddibot | C34: Corte y/o Barrenado | D34: Biselado | E34: Verificacion Calidad | G34: Biselado | H34: Corte y/o Barrenado | I34: Biselado | J34: Verificacion Calidad
B35: Tiempo de Ciclo | C35: =1+25 -> 26 | E35: 65 | G35: Tiempo de Ciclo | I35: 60
B36: Numero de Operarios | C36: 2 | G36: Numero de Operarios | I36: 8
B37: Numero de Turnos | C37: 2 | G37: Numero de Turnos | I37: 2
B38: Piezas disponibles antes | C38: 6 placas | G38: Piezas disponibles antes | H38: 96 piezas
B39: Superfice M2 | C39: =24*4 -> 96 | G39: Superfice M2 | I39: =30*5 -> 150
B40: Q/R | C40: 0.3556 | G40: Q/R | I40: 0.9444
B42: Corte FBP | C42: Corte y/o Barrenado | D42: Biselado | E42: Verificacion Calidad | G42: Corte BDL | H42: Corte y/o Barrenado | I42: Biselado | J42: Verificacion Calidad
B43: Tiempo de Ciclo | C43: 45 | G43: Tiempo de Ciclo | H43: 45
B44: Numero de Operarios | D44: 2 | G44: Numero de Operarios | I44: 2
B45: Numero de Turnos | D45: 2 | G45: Numero de Turnos | I45: 2
B46: Piezas disponibles antes | C46: 6 placas | G46: Piezas disponibles antes | H46: 26 perfiles
B47: Superfice M2 | D47: 96 | G47: Superfice M2 | I47: 96
...

Sheet Familia de Producto
A1: Eleccion de Productos
E3: 1 | F3: 2 | G3: 3 | H3: 4 | I3: 5 | J3: 6 | K3: 7
A4: Marca | B4: Corte Placa Hight Speed | C4: Corte Perfil BDL | D4: Corte de Placas Menor FBP 3/4" | E4: Corte Perfil Peddbot | F4: Corte Bisel Manual | G4: Corte Ironwork | H4: Sierra pequeña
A5: Columnas de Fachada | B5: X | C5: X | D5: X | E5: X | F5: X
A6: Columnas Interna | B6: X | C6: X | F6: X | J6: Familia de Productos
A7: Trabes Principales | B7: X | C7: X | D7: X | F7: X
A8: Trabes secundarias | C8: X | D8: X
A9: Trabes directas | E9: X
A10: Structs | H10: X
A11: Contra flambeos | G11: X
A12: Contra vientos | D12: X | G12: X | H12: X
A13: Montenes | H13: X

Sheet VSM Columnas Perimetral Actual
M2: Terreno Materia Almacen Primario de Materia Prima
K17: Area de Habilitado para produccion de armables en Planta Metalmecanica
C18: Area de descarga Materia Prima
L20: Takt | M20: 16 | N20: =+M20/M21 -> 0.47058824 | O20: Horas/toneladas
M21: 34
C22: Anden
L23: Pitch Time | M23: 16 | N23: =+M23/M24 -> 1.4545455 | O23: Horas/toneladas
C24: Alamcen Placas | F24: Almacen de Perfiles | M24: 11
C31: Usado Para Chatarra Actualmente
K36: Corte de Placa
L37: 2
K38: Maquina Thor Placa
K39: T. Disponible | L39: 16
K40: C/T | L40: 3
K41: C/O | L41: 0.5
K42: Up-Time | L42: 14
K43: Q/R | L43: =+(120-15)/120 -> 0.875
K44: Lote
D47: Corte de Placa | H47: Almacen de Partes
E48: 2
D49: Maquina Hight Speed
D50: T. Disponible | E50: 16
D51: C/T | E51: 3
D52: C/O | E52: 0.5
D53: Up-Time | E53: 12
D54: Q/R | E54: =+(260-5)/260 -> 0.98076923
D55: Lote
C60: Biselado de Placa
D61: 4
C62: Maquina semi atomaticas
C63: T. Disponible | D63: 16 | K63: Corte Perfil | U63: 1 Carro de distribucion de Perfiles
C64: C/T | D64: 1 | L64: 2 | O64: Alamacen de Partes | W64: Nave 3
C65: C/O | D65: 0.2 | K65: Maquina BDL | S65: Alamacen de perfiles
C66: Up-Time | D66: 12 | K66: T. Disponible | L66: 16
C67: Q/R | D67: =+(18-1)/18 -> 0.94444444 | K67: C/T | L67: 0.2
C68: Lote | K68: C/O | L68: 0.1
K69: Up-Time | L69: 14
K70: Q/R | L70: =+(123-14)/123 -> 0.88617886
K71: Lote
K74: Corte de Placa | O74: Area Formacion de Paquetes
...
