Workbook
Name OUT_ALERTAS_AREA: '14_INTERFAZ_MOTOR'!$C$29
Name OUT_AREA_M2: '14_INTERFAZ_MOTOR'!$C$17
Name OUT_COSTO_ABRASIVO: '14_INTERFAZ_MOTOR'!$C$25
Name OUT_COSTO_APLICACION: '14_INTERFAZ_MOTOR'!$C$26
Name OUT_COSTO_KG: '14_INTERFAZ_MOTOR'!$C$28
Name OUT_COSTO_M2: '14_INTERFAZ_MOTOR'!$C$27
Name OUT_COSTO_PINTURA: '14_INTERFAZ_MOTOR'!$C$23
Name OUT_CUNETES: '14_INTERFAZ_MOTOR'!$C$22
Name OUT_KG_ABRASIVO: '14_INTERFAZ_MOTOR'!$C$24
Name OUT_LITROS_DESPERDICIO: '14_INTERFAZ_MOTOR'!$C$21
Name OUT_LITROS_PRACTICOS: '14_INTERFAZ_MOTOR'!$C$20
Name OUT_LITROS_TEORICOS: '14_INTERFAZ_MOTOR'!$C$19
Name OUT_PESO_KG: '14_INTERFAZ_MOTOR'!$C$18
Name OUT_PU_CELOSIA: '14_INTERFAZ_MOTOR'!$C$35
Name OUT_PU_COLUMNA: '14_INTERFAZ_MOTOR'!$C$33
Name OUT_PU_CONTRAVENTEO: '14_INTERFAZ_MOTOR'!$C$36
Name OUT_PU_MISCELANEO: '14_INTERFAZ_MOTOR'!$C$37
Name OUT_PU_PLACA: '14_INTERFAZ_MOTOR'!$C$38
Name OUT_PU_VIGA: '14_INTERFAZ_MOTOR'!$C$34

Sheet 0_PASO_A_PASO
B2: INSTRUCTIVO PASO A PASO — ESTIMACIÓN DE APLICACIÓN DE PINTURA
B3: Siga los pasos en orden. Tiempo estimado la primera vez: 2–3 horas con el modelo en mano; 30–45 min en proyectos siguientes (los factores ya quedan calibrados). Regla general del archivo: solo se capturan celdas AZULES; las negras y verdes se calculan solas. Celdas con fondo AMARILLO = supuestos que exigen calibración antes de usar en una oferta.
B5: FASE 0 — ANTES DE ABRIR EL ARCHIVO: REÚNA LA INFORMACIÓN
B6: 0.1 | C6: Documentos del proyecto | D6: Tenga a la mano: (a) la especificación de pintura del proyecto (sistema de capas, EPS por capa, grado de limpieza SP y perfil de anclaje requerido, categoría de corrosividad C1–C5 y, si aplica, el rating ignífugo R30/R60/R90/R120); (b) las hojas técnicas (TDS) de cada producto del sistema propuesto; (c) el reporte de piezas del modelo Tekla/IFC con áreas y pesos, o —si aún no hay modelo— el tonelaje estimado por familia; (d) cotizaciones vigentes de pintura (por cuñete) y abrasivo (por saco o súper saco).
B7: 0.2 | C7: Verifique compatibilidad del sistema | D7: Confirme en los TDS que las capas son compatibles entre sí (el fabricante lo indica) y que el primario está aprobado para el perfil de anclaje especificado. Si hay intumescente, pida al fabricante la CARTA DE ESPESORES CERTIFICADA (por Hp/A y rating) — sin ella no se puede presupuestar en serio. Este es un punto de decisión suya, no del archivo.
B8: 0.3 | C8: Defina el alcance de aplicación | D8: Aclare con el cliente qué se pinta en taller y qué en obra, si el retoque de montaje está en su alcance, y qué superficies quedan explícitamente SIN pintura (slip-critical, embebidos, zonas de soldadura de campo). Esto cambia áreas, ambientes de aplicación y responsabilidades.
B9: FASE 1 — CAPTURE LOS PRODUCTOS (HOJA 2_HOJA_TECNICA)
B10: 1.1 | C10: Un renglón por producto | D10: Capture cada producto del sistema (primario, intermedio, acabado, intumescente, sellador si aplica) en un renglón: nombre comercial, fabricante, tipo genérico, % sólidos por volumen (del TDS, "sin diluir"), EPS mínimo/recomendado/máximo, litros por cuñete, si es intumescente (SI/NO) y precio por cuñete de la cotización vigente.
B11: 1.2 | C11: Cuidado con el % de sólidos | D11: El TDS a veces da dos valores: sólidos por VOLUMEN y sólidos por PESO. El que usa este modelo es POR VOLUMEN. Si el TDS solo da por peso, pida el dato al proveedor. Capturarlo mal distorsiona todo el rendimiento.
B12: 1.3 | C12: Verifique el rendimiento calculado | D12: La columna "Rend. teórico" debe parecerse al rendimiento teórico que declara el propio TDS al mismo espesor. Si difiere más de ±5%, hay un error de captura (espesor en mils en lugar de micras es el clásico).
B13: FASE 2 — CALIBRE LOS FACTORES DE DESPERDICIO (HOJA 3_FACTORES)
B14: 2.1 | C14: Primera vez: revise, no acepte | D14: Las tablas A (forma), B (ambiente/método), C (perfil de anclaje) y D (entre capas, equipo, intumescente, franjeo) traen valores típicos de la industria. NO son de METALITEC: son el punto de partida. Léalas con su supervisor de pintura y ajuste lo que su experiencia contradiga.
B15: 2.2 | C15: Calibración con datos reales | D15: La calibración seria se hace así: tome 3–5 órdenes de trabajo cerradas, con litros realmente consumidos (vales de almacén) y m² realmente pintados por tipo de pieza. Calcule el consumo real por m², compárelo contra el teórico del TDS y despeje el % de pérdida real. Ajuste las tablas hasta que el modelo reproduzca esos consumos históricos con ±5% de error. Documente la fecha de calibración en un comentario de celda.
B16: 2.3 | C16: Perfil de anclaje | D16: En la Tabla C verifique que el rango de perfil corresponda a lo que su granalladora realmente produce (mídalo con cinta réplica Testex en 2–3 piezas). Si su mezcla operativa da 65 µm y el proyecto pide 50–75, use R2/R3 según el caso.
B17: FASE 3 — DETERMINE EL ÁREA A PINTAR (HOJAS 12_ESTIMACION Y 10_PIEZAS)
B18: 3.1 | C18: ¿Tiene modelo o solo tonelaje? | D18: CAMINO A (sin modelo, cotización temprana): vaya a 12_ESTIMACION, capture el espesor promedio por familia (mm) y el % de área no pintable; con el tonelaje obtiene los m² estimados pintables. Use esos m² para las fases 4–6. CAMINO B (con modelo Tekla/IFC): llene 10_PIEZAS con el reporte de piezas — marca, familia, cantidad, área y peso unitarios — y use las áreas reales. Puede subir el archivo de exportación a Claude para que llene la tabla.
B19: 3.2 | C19: Pida el reporte correcto | D19: Al área del modelo pídale SOLO área pintable: sin interior de HSS, sin caras de contacto con concreto, sin superficies slip-critical. Si el reporte trae área total (lo usual en Tekla), descuéntelo con el % no pintable de 12_ESTIMACION, columna F.
B20: 3.3 | C20: Valide con el semáforo | D20: Con ambos caminos disponibles, 12_ESTIMACION compara estimado vs. real por familia. Si una familia marca ⚠ REEVALUAR (diferencia > tolerancia, default ±15%), NO avance: revise en este orden (a) el espesor promedio supuesto contra los perfiles reales de esa familia, (b) si el reporte del modelo incluye superficies no pintables, (c) piezas duplicadas o faltantes en 10_PIEZAS. Avanzar con áreas malas invalida todo lo que sigue.
B21: FASE 4 — CALCULE CONSUMO Y DESPERDICIO DE PINTURA (HOJA 4_CALCULO)
B22: 4.1 | C22: Arme las partidas | D22: Agrupe las piezas en partidas que compartan: misma forma dominante (F1–F7), mismo ambiente/método (A1–A6), mismo perfil de anclaje (R0–R4) y mismo sistema de capas. Típicamente coinciden con las familias de 10_PIEZAS, pero puede subdividir (p. ej., "vigas con ignífugo" aparte de "vigas normales").
B23: 4.2 | C23: Una fila por capa | D23: Cada partida ocupa tantas filas como capas tenga el sistema: capa 1 = primario, capa 2 = intermedio, capa 3 = acabado (y las que apliquen: intumescente, sellador). Repita en cada fila el área y los códigos de la partida; cambie solo el N° de capa, el ID de producto y el EPS especificado de esa capa.
B24: 4.3 | C24: Franjeo en la capa correcta | D24: Marque "SI" en franjeo normalmente en la capa 1 (o donde la especificación pida el stripe coat). No lo marque en todas las capas: duplicaría el recargo.
B25: 4.4 | C25: Lea los resultados | D25: Por cada capa el modelo entrega: EPS corregido (la capa 1 sube por el volumen muerto del perfil de anclaje), rendimiento teórico, litros teóricos, % de pérdida total compuesta, litros prácticos y LITROS DE DESPERDICIO explícitos. Verifique que los % de pérdida le hagan sentido: placa en taller ~15–20%, viga W ~25%, celosía ~45–50%, intumescente +12 puntos adicionales. Si algo sale fuera de esos órdenes, revise los códigos capturados.
B26: FASE 5 — ABRASIVO (HOJA 7_ABRASIVO)
B27: 5.1 | C27: Elija el sistema de blasteo | D27: Por partida: AB2 si la pieza pasa por la máquina de granallado (lo normal en perfiles), AB3 si va a cuarto manual (piezas fuera de gálibo, retrabajos), AB1 solo si se blastea con arena/escoria a cielo abierto (campo). El grado (SP6/SP10/SP5) viene de la especificación del proyecto.
B28: 5.2 | C28: Capture precios y presentaciones | D28: En la Tabla E ponga el precio vigente por presentación (saco 25 kg de granalla, súper saco de arena) y ajuste la presentación a la de su proveedor. El modelo redondea la compra a presentaciones completas.
B29: 5.3 | C29: Calibre la atrición | D29: El consumo de granalla precargado (kg/m²) es genérico. Su dato real: kg de granalla repuestos en el periodo ÷ m² procesados en el mismo periodo (vales de almacén vs. reporte de producción). Es el número que más varía entre plantas.
B30: FASE 6 — COMPRA Y APU (HOJAS 5_RESUMEN Y 11_APU)
B31: 6.1 | C31: Revise la compra en cuñetes | D31: 5_RESUMEN consolida litros prácticos por producto, redondea a cuñetes completos (ROUNDUP) y muestra el colchón de redondeo y el costo. Verifique: (a) que ningún producto quede con consumo cero inesperado, (b) que el colchón de redondeo sea razonable — si un producto compra 1 cuñete para usar 2 litros, evalúe presentación menor o compartir con otra OT.
B32: 6.2 | C32: Arme el APU por familia | D32: En 11_APU: copie las referencias verdes de material ($/m² pintura y abrasivo del proyecto) como punto de partida en las columnas azules, ajuste por familia si los sistemas difieren, capture HH/m² por familia (calibre con OTs reales — misma disciplina que su HH/ton), tarifa $/HH, equipo $/m² y el % de indirectos + utilidad según la política comercial vigente.
B33: 6.3 | C33: Elija la unidad de venta | D33: Seleccione m2 o kg por familia según cómo cotiza el cliente. Verifique el PU en kg contra su intuición: la celosía SIEMPRE debe salir varias veces más cara por kg que la placa. Si no, hay un error de áreas o de ratio kg/m².
B34: 6.4 | C34: Costo por pieza | D34: 10_PIEZAS ya muestra el costo de pintura por pieza, en $/m² y $/kg, tomando el PU de su familia. Útil para valuar avances, cambios de alcance y reclamos.
B35: FASE 7 — VALIDACIÓN FINAL ANTES DE OFERTAR (ZONA COPILOTO: SU FIRMA)
B36: 7.1 | C36: Checklist de cierre | D36: Antes de pasar los números a la oferta verifique: □ ninguna familia en ⚠ REEVALUAR en 12_ESTIMACION; □ factores de 3_FACTORES calibrados o al menos revisados con el supervisor; □ TDS reales capturados (no los ejemplos P01–P04); □ precios de pintura y abrasivo con cotización vigente (no en cero); □ si hay intumescente, EPS tomado de la carta certificada por Hp/A, no de la tabla ilustrativa; □ % indirectos + utilidad autorizado por dirección.
B37: 7.2 | C37: Prueba de sensibilidad | D37: Cambie ±10% el factor de forma dominante y el precio del producto más caro, y observe cuánto se mueve el costo total. Si la oferta es sensible (>5% del total), documente el supuesto en la oferta como condición (p. ej., "considera aplicación en taller; aplicación en campo se cotiza aparte").
B38: 7.3 | C38: Cierre del ciclo (mejora continua) | D38: Al terminar el proyecto, compare litros comprados vs. consumidos vs. lo que este modelo predijo, por producto y por partida. La diferencia alimenta la recalibración de 3_FACTORES y 7_ABRASIVO (paso 2.2). Con 3–4 proyectos cerrados, el modelo queda ajustado a SU planta y las ofertas se vuelven defendibles con datos, no con criterio.
B39: 7.4 | C39: Errores comunes a evitar | D39: (1) Capturar EPS en mils creyendo que son micras (todo el consumo sale 25 veces mal). (2) Usar el área total del modelo sin descontar no pintables. (3) Olvidar el sellador del intumescente como capa. (4) Marcar franjeo en todas las capas. (5) Presupuestar intumescente con un EPS promedio en lugar de por Hp/A. (6) Dejar precios en cero y ofertar solo con litros. (7) No respetar la ventana máxima de repintado en la programación: el lijado no está en este modelo y come el margen.
B41: Recuerde el marco de trabajo: este archivo PROPONE (Zona Copiloto). Los factores calibrados, los precios, la unidad de venta y la oferta final los valida y firma la dirección. Ningún número sale de aquí a un cliente sin pasar por los pasos 7.1 a 7.3.
B43: ACTUALIZACIÓN: use la hoja 13_PANEL como tablero de captura y resultados (uso directo en Excel), la hoja 14_INTERFAZ_MOTOR para la integración con el Motor IFC/presupuesto, y el asistente de 6_IGNIFUGO para repartir el intumescente entre planta y sitio (dos filas en 4_CALCULO: planta=A1, sitio=A4/A6).
B44: ACTUALIZACIÓN 2: antes de calcular el abrasivo, determine la condición inicial del acero (grados A/B/C/D de ISO 8501-1, Tabla F de 7_ABRASIVO) inspeccionando el material en patio: acero nuevo con calamina o acero viejo picado consumen 30–90% más abrasivo que la condición base, y el acero picado altera el perfil de anclaje real (medir con Testex y ajustar la Tabla C).

Sheet 13_PANEL
B2: PANEL DE CONTROL — CAPTURA GUIADA Y RESULTADOS
B3: Una sola vista para usar el archivo sin perderse: la columna ESTADO le dice qué falta por capturar (se pone OK sola cuando termina cada paso) y abajo están los resultados del presupuesto en vivo. El detalle vive en las demás hojas; aquí solo se supervisa.
B5: CHECKLIST DE CAPTURA (en orden)
B6: Paso | C6: Estado | E6: Dónde y qué capturar
B7: 1. Productos de pintura (TDS) capturados | C7: =IF(COUNT('2_HOJA_TECNICA'!F6:F13)>=1,"OK","FALTA") -> OK | E7: Hoja 2_HOJA_TECNICA: un renglón por producto con % sólidos por volumen, espesores y litros por cuñete, copiados de la hoja técnica.
B8: 2. Precios de pintura capturados | C8: =IF(SUMPRODUCT(--('2_HOJA_TECNICA'!L6:L13>0))>=1,"OK","FALTA") -> FALTA | E8: Hoja 2_HOJA_TECNICA columna L: precio por cuñete de la cotización vigente. Sin precio, el costo sale en cero.
B9: 3. Factores de desperdicio revisados | C9: =IF($C$16="SI","OK","PENDIENTE") -> PENDIENTE | E9: Hoja 3_FACTORES: revise las 4 tablas con su supervisor de pintura y ajuste las celdas amarillas. Cuando lo haga, ponga SI en la celda azul de la derecha →
B10: 4. Piezas o áreas capturadas | C10: =IF(COUNTA('10_PIEZAS'!B6:B35)>=1,"OK","FALTA") -> OK | E10: Hoja 10_PIEZAS (si hay modelo Tekla/IFC) o hoja 12_ESTIMACION (si solo hay tonelaje: espesor promedio + % no pintable por familia).
B11: 5. Áreas validadas (sin alertas) | C11: =IF(COUNTIF('12_ESTIMACION'!K8:K13,"⚠ REEVALUAR")=0,"OK",COUNTIF('12_ESTIMACION'!K8:K13,"⚠ REEVALUAR")&" FAMILIAS EN ALERTA") -> 5 FAMILIAS EN ALERTA | E11: Hoja 12_ESTIMACION: ninguna familia debe quedar en ⚠ REEVALUAR. Si hay alertas, corrija espesor promedio, % no pintable o el listado de piezas antes de seguir.
B12: 6. Partidas y capas capturadas | C12: =IF(COUNTA('4_CALCULO'!B6:B25)>=1,"OK","FALTA") -> OK | E12: Hoja 4_CALCULO: una fila por capa de cada partida. Si hay intumescente, capture DOS filas (planta y sitio) usando el asistente de 6_IGNIFUGO.
B13: 7. Abrasivo capturado con precio | C13: =IF(AND(COUNTA('7_ABRASIVO'!B14:B28)>=1,SUMPRODUCT(--('7_ABRASIVO'!J7:J9>0))>=1),"OK","FALTA") -> FALTA | E13: Hoja 7_ABRASIVO: partidas de blasteo + precio por presentación de arena/granalla en la Tabla E.
B14: 8. APU armado (MO, equipo, indirectos) | C14: =IF(SUMPRODUCT(--('11_APU'!G7:G12>0))>=1,"OK","PENDIENTE") -> PENDIENTE | E14: Hoja 11_APU: copie las referencias verdes de material a las columnas azules, capture HH/m², tarifa, equipo e indirectos, y elija la unidad m2/kg por familia.
B16: Confirmación factores revisados (escriba SI): | C16: NO
B18: RESULTADOS DEL PRESUPUESTO (en vivo)
B19: Indicador | C19: Valor
B20: Área pintable total (m²) | C20: ='10_PIEZAS'!H36 -> 1348.8
B21: Peso total (kg) | C21: ='10_PIEZAS'!I36 -> 69782
B22: Pintura — litros teóricos | C22: ='4_CALCULO'!N26 -> 1782.418
B23: Pintura — litros prácticos (con desperdicio) | C23: ='4_CALCULO'!P26 -> 2704.9836
B24: Pintura — litros de desperdicio | C24: ='4_CALCULO'!Q26 -> 922.56554
B25: Pintura — % desperdicio global | C25: =IF('4_CALCULO'!P26=0,"",'4_CALCULO'!Q26/'4_CALCULO'!P26) -> 0.34106142
B26: Pintura — cuñetes a comprar (total) | C26: ='5_RESUMEN'!I14 -> 127
B27: Pintura — costo de compra ($) | C27: ='5_RESUMEN'!L14 -> 0
B28: Abrasivo — kg a comprar | C28: ='7_ABRASIVO'!M29 -> 3650
B29: Abrasivo — costo de compra ($) | C29: ='7_ABRASIVO'!N29 -> 0
B30: Aplicación — costo total según APU ($) | C30: ='10_PIEZAS'!K36 -> 29671.312
B31: Aplicación — costo promedio $/m² | C31: =IF('10_PIEZAS'!H36=0,"",'10_PIEZAS'!K36/'10_PIEZAS'!H36) -> 21.998304
B32: Aplicación — costo promedio $/kg | C32: ='10_PIEZAS'!L36 -> 0.42520009
B34: Si todos los pasos del checklist están en OK y las cifras de arriba le hacen sentido, pase al checklist de cierre 7.1 del instructivo (hoja 0_PASO_A_PASO) antes de llevar estos números a la oferta.

Sheet 1_INSTRUCCIONES
B2: MOTOR DE PRESUPUESTO — MÓDULO PINTURA: DESPERDICIOS Y COMPRA EN CUÑETES
B3: METALITEC / Grupo Baysa — Sistemas de pintura sobre acero estructural (SSPC / ISO 12944)
B5: OBJETIVO | C5: Determinar la cantidad de pintura a comprar (en cuñetes) por cada producto del sistema, partiendo de la hoja técnica del fabricante, el perfil de anclaje especificado y el área a pintar, incorporando de forma explícita y auditable los factores de desperdicio: forma de la pieza, ambiente de aplicación, método de aplicación, corrección por perfil de anclaje y pérdidas entre capas. Incluye consideraciones para pinturas ignífugas (intumescentes).
B6: FLUJO DE USO | C6: 1) Capture cada producto de pintura en la hoja 2_HOJA_TECNICA transcribiendo los datos de la hoja técnica (TDS) del fabricante: % sólidos por volumen, EPS recomendado, presentación del cuñete, si es intumescente, etc. 2) Revise/calibre los factores de las tablas en 3_FACTORES (celdas azules = editables). 3) En 4_CALCULO capture cada partida: área, forma, ambiente, método, perfil de anclaje y el sistema de capas (producto + EPS por capa). 4) Lea el resultado: litros teóricos, % desperdicio total, litros prácticos y cuñetes a comprar. 5) 5_RESUMEN consolida la compra por producto. 6) Si hay intumescente, revise 6_IGNIFUGO para masividad Hp/A y sus reglas.
B7: CONVENCIÓN DE COLORES | C7: AZUL = dato de entrada (usted lo captura o calibra). NEGRO = fórmula (no tocar). VERDE = vínculo entre hojas. Fondo AMARILLO = supuesto clave que requiere calibración con datos reales de planta antes de usar en oferta.
B8: FÓRMULA BASE (SSPC) | C8: Rendimiento teórico (m²/L) = (% Sólidos por Volumen × 10) / EPS seco (µm). Consumo teórico (L) = Área (m²) / Rendimiento teórico. Consumo práctico (L) = Consumo teórico / (1 − % pérdida total). La pérdida total se compone multiplicativamente: (1−pérdida) = (1−p.forma) × (1−p.ambiente/método) × (1−p.entre capas), y la capa 1 lleva además la corrección de volumen muerto por perfil de anclaje.
B9: PERFIL DE ANCLAJE | C9: La rugosidad del granallado (p. ej. SSPC-SP10 con perfil 50–75 µm) consume pintura: los picos del perfil "roban" espesor a la primera capa (volumen muerto). Regla práctica de la industria (Hempel, Jotun, NACE): sumar al EPS de la capa 1 una corrección ≈ 1/3 a 2/3 del perfil de anclaje según rugosidad. La tabla en 3_FACTORES define la corrección por rango de perfil; solo aplica a la CAPA 1 (primario).
B10: DESPERDICIO REPORTADO | C10: El modelo reporta, por cada capa y por cada producto, el % de desperdicio total considerado y los litros de desperdicio (diferencia entre consumo práctico y teórico), para que Comercial pueda defender el APU y Compras conozca el excedente implícito.
B11: IGNÍFUGAS | C11: Si el producto está marcado como intumescente en 2_HOJA_TECNICA, el cálculo aplica automáticamente el recargo adicional de desperdicio de la tabla de 3_FACTORES (múltiples pasadas, alto espesor, malla en algunos casos) y la hoja 6_IGNIFUGO da la guía de EPS por masividad Hp/A. El EPS de intumescente NO sale del TDS genérico: sale del certificado del fabricante según Hp/A y tiempo de resistencia al fuego requerido (30/60/90/120 min). Zona Humana: la validación del espesor certificado es indelegable.
B12: ZONA COPILOTO | C12: La IA propone los factores típicos de la industria precargados; Daniel valida y calibra con mediciones reales de planta (consumo real vs. teórico por OT) y firma los volúmenes de compra. Los valores precargados NO deben usarse en una oferta sin calibración.

Sheet 2_HOJA_TECNICA
B2: CATÁLOGO DE PRODUCTOS — DATOS DE HOJA TÉCNICA (TDS) DEL FABRICANTE
B3: Capture en AZUL los datos tal como aparecen en la hoja técnica. Las columnas en negro se calculan solas.
B5: ID | C5: Producto / Nombre comercial | D5: Fabricante | E5: Tipo genérico | F5: % Sólidos x Volumen | G5: EPS mín (µm) | H5: EPS recom (µm) | I5: EPS máx (µm) | J5: Cuñete (L) | K5: ¿Intumescente? (SI/NO) | L5: Precio x cuñete ($) | M5: Rend. teórico @EPS recom (m²/L) | N5: Rend. teórico (m²/cuñete) | O5: Notas TDS (diluyente, pot-life, repintado)
B6: P01 | C6: Primario epóxico rico en zinc | D6: (capturar) | E6: Zinc epóxico | F6: 0.62 | G6: 50 | H6: 75 | I6: 100 | J6: 18.9 | K6: NO | L6: 0 | M6: =IF(OR(F6="",H6=""),"",F6*1000/H6) -> 8.2666667 | N6: =IF(M6="","",M6*J6) -> 156.24
B7: P02 | C7: Epóxico poliamida alto sólidos | D7: (capturar) | E7: Epóxico intermedio | F7: 0.8 | G7: 100 | H7: 125 | I7: 200 | J7: 18.9 | K7: NO | L7: 0 | M7: =IF(OR(F7="",H7=""),"",F7*1000/H7) -> 6.4 | N7: =IF(M7="","",M7*J7) -> 120.96
B8: P03 | C8: Acabado poliuretano alifático | D8: (capturar) | E8: Poliuretano acabado | F8: 0.6 | G8: 50 | H8: 75 | I8: 100 | J8: 18.9 | K8: NO | L8: 0 | M8: =IF(OR(F8="",H8=""),"",F8*1000/H8) -> 8 | N8: =IF(M8="","",M8*J8) -> 151.2
B9: P04 | C9: Intumescente base agua | D9: (capturar) | E9: Intumescente celulósico | F9: 0.69 | G9: 300 | H9: 1000 | I9: 3000 | J9: 25 | K9: SI | L9: 0 | M9: =IF(OR(F9="",H9=""),"",F9*1000/H9) -> 0.69 | N9: =IF(M9="","",M9*J9) -> 17.25
B10: P05 | K10: NO | L10: 0 | M10: =IF(OR(F10="",H10=""),"",F10*1000/H10) | N10: =IF(M10="","",M10*J10)
B11: P06 | K11: NO | L11: 0 | M11: =IF(OR(F11="",H11=""),"",F11*1000/H11) | N11: =IF(M11="","",M11*J11)
B12: P07 | K12: NO | L12: 0 | M12: =IF(OR(F12="",H12=""),"",F12*1000/H12) | N12: =IF(M12="","",M12*J12)
B13: P08 | K13: NO | L13: 0 | M13: =IF(OR(F13="",H13=""),"",F13*1000/H13) | N13: =IF(M13="","",M13*J13)
B14: Nota: Rend. teórico (m²/L) = %SV × 10 / EPS(µm) × 100 = %SV × 1000 / EPS. Ejemplo: 62% SV @ 75 µm → 8.27 m²/L. Los productos P01–P04 son EJEMPLOS genéricos: sustituya con el TDS real del proyecto.

Sheet 3_FACTORES
B2: TABLAS DE FACTORES DE DESPERDICIO (CALIBRAR CON DATOS DE PLANTA)
B4: TABLA A — FACTOR DE FORMA DE LA PIEZA (pérdida por overspray según geometría)
B5: Código | C5: Descripción de la pieza | D5: % Pérdida forma | G5: Criterio
B6: F1 | C6: Placa / superficie plana continua (tanques, placas) | D6: 0.05 | G6: Superficie continua, overspray mínimo; el abanico casi todo deposita.
B7: F2 | C7: Perfil pesado W/HP alma ancha (>200 mm de patín) | D7: 0.1 | G7: Caras anchas pero con cantos y filetes; algo de rebote en esquinas interiores.
B8: F3 | C8: Perfil mediano W/C/L (100–200 mm) | D8: 0.15 | G8: Relación perímetro/área alta; el abanico excede el ancho de la cara.
B9: F4 | C9: Perfil ligero / ángulos / redondos (<100 mm) | D9: 0.25 | G9: Gran parte del abanico pasa de largo; piezas angostas.
B10: F5 | C10: Celosía / armadura / joist (estructura abierta) | D10: 0.4 | G10: Estructura abierta: el aire pasa a través; pérdida típica 35–50%.
B11: F6 | C11: HSS / tubulares (solo exterior) | D11: 0.12 | G11: Superficie curva continua, pero el abanico envuelve y escapa tangencialmente.
B12: F7 | C12: Miscelánea compleja (conexiones, escaleras, barandal) | D12: 0.3 | G12: Geometría irregular, muchas caras pequeñas, retoque con brocha.
B15: TABLA B — AMBIENTE Y MÉTODO DE APLICACIÓN (pérdida por condiciones + eficiencia de transferencia)
B16: Código | C16: Ambiente / Método | D16: % Pérdida amb+mét | G16: Criterio
B17: A1 | C17: Taller controlado — Airless | D17: 0.1 | G17: Cabina/nave cerrada, sin viento; airless con eficiencia de transferencia 70–80%.
B18: A2 | C18: Taller controlado — Convencional (aire) | D18: 0.25 | G18: Pistola convencional: eficiencia 45–60% aun en ambiente controlado.
B19: A3 | C19: Taller controlado — Brocha/Rodillo | D19: 0.05 | G19: Casi sin overspray; pérdida por residuo en charola/rodillo y retoques.
B20: A4 | C20: Exterior / campo — Airless | D20: 0.2 | G20: Viento y condiciones variables: overspray se duplica vs. taller; incluye deriva.
B21: A5 | C21: Exterior / campo — Convencional (aire) | D21: 0.35 | G21: La peor combinación: baja transferencia + viento. Evitar si es posible.
B22: A6 | C22: Exterior / campo — Brocha/Rodillo (retoque montaje) | D22: 0.08 | G22: Retoques en obra: pérdida baja de aplicación pero botes abiertos y sobrantes.
B25: TABLA C — CORRECCIÓN POR PERFIL DE ANCLAJE (volumen muerto — SOLO CAPA 1 / PRIMARIO)
B26: Código | C26: Perfil de anclaje especificado | D26: Perfil (µm) | E26: µm extra a sumar al EPS capa 1 | G26: Criterio
B27: R0 | C27: Sin granallado / SP2-SP3 (limpieza manual) | D27: 0 | E27: 0 | G27: Sin perfil generado: no hay volumen muerto significativo.
B28: R1 | C28: Perfil fino 25–40 µm (SP6 ligero) | D28: 40 | E28: 15 | G28: ≈1/3 del perfil: rugosidad fina, poco volumen muerto.
B29: R2 | C29: Perfil medio 40–60 µm (SP6 / SP10 típico) | D29: 60 | E29: 25 | G29: ≈40–50% del perfil. Rango más común en estructura.
B30: R3 | C30: Perfil grueso 60–85 µm (SP10 / SP5 con abrasivo angular) | D30: 85 | E30: 40 | G30: ≈50% del perfil: picos altos consumen primario.
B31: R4 | C31: Perfil muy grueso >85 µm (granalla angular gruesa / intumescente) | D31: 100 | E31: 60 | G31: ≈60% del perfil; usual para intumescentes y zinc silicato.
B34: TABLA D — PÉRDIDAS ENTRE CAPAS Y RECARGOS ADICIONALES
B35: Código | C35: Concepto | D35: % Pérdida | G35: Criterio
B36: D1 | C36: Pérdida entre capas (capa 2 en adelante) | D36: 0.05 | G36: Retoques de puntos bajos detectados con medidor, lijado/reactivación, franjeo (stripe coat) no medido aparte.
B37: D2 | C37: Residuo en envase, mangueras y equipo (por producto/lote) | D37: 0.04 | G37: Pintura que queda en cuñete, bomba, mangueras, filtros y purgas al cambiar de color/producto.
B38: D3 | C38: Recargo pintura INTUMESCENTE (adicional) | D38: 0.12 | G38: Altos espesores en múltiples pasadas, descuelgues, control de EPS húmedo pasada por pasada, mermas por pot-life en base solvente.
B39: D4 | C39: Recargo franjeo / stripe coat en cantos y soldaduras (si no se cuantifica su área) | D39: 0.03 | G39: Cordón adicional a brocha en cantos, tornillos y soldaduras; consume producto no capturado en el área plana.
B41: Composición: (1−Pérdida total) = (1−forma) × (1−amb/mét) × (1−entre capas si aplica) × (1−residuo equipo) × (1−intumescente si aplica) × (1−franjeo si aplica). La corrección por perfil de anclaje NO es un %: se suma en µm al EPS de la capa 1.

Sheet 4_CALCULO
B2: CÁLCULO DE CONSUMO Y DESPERDICIO POR PARTIDA Y CAPA
B3: Una fila por CAPA de cada partida. Capture las celdas azules; use los códigos de 3_FACTORES y los ID de producto de 2_HOJA_TECNICA.
B5: Partida | C5: Descripción | D5: Área (m²) | E5: Forma (F1-F7) | F5: Amb/Mét (A1-A6) | G5: Perfil ancl. (R0-R4) | H5: N° capa (1,2,3…) | I5: ID Prod. | J5: EPS espec. capa (µm) | K5: ¿Franjeo? (SI/NO) | L5: EPS corregido (µm) | M5: Rend. teórico (m²/L) | N5: Litros teóricos | O5: % Pérdida total | P5: Litros prácticos | Q5: Litros desperdicio | R5: Cuñete (L) | S5: Cuñetes (info capa)
B6: PT-01 | C6: Vigas principales W24 nave | D6: 1250 | E6: F2 | F6: A1 | G6: R2 | H6: 1 | I6: P01 | J6: 75 | K6: SI | L6: =IF($B6="","",J6+IF(H6=1,VLOOKUP(G6,'3_FACTORES'!$B$27:$E$31,4,0),0)) -> 100 | M6: =IF($B6="","",VLOOKUP(I6,'2_HOJA_TECNICA'!$B$6:$K$13,5,0)*1000/L6) -> 6.2 | N6: =IF($B6="","",D6/M6) -> 201.6129 | O6: =IF($B6="","",1-(1-VLOOKUP(E6,'3_FACTORES'!$B$6:$D$12,3,0))*(1-VLOOKUP(F6,'3_FACTORES'!$B$17:$D$22,3,0))*(1-IF(H6>1,'3_FACTORES'!$D$36,0))*(1-'3_FACTORES'!$D$37)*(1-IF(VLOOKUP(I6,'2_HOJA_TECNICA'!$B$6:$K$13,10,0)="SI",'3_FACTORES'!$D$38,0))*(1-IF(K6="SI",'3_FACTORES'!$D$39,0))) -> 0.245728 | P6: =IF($B6="","",N6/(1-O6)) -> 267.29469 | Q6: =IF($B6="","",P6-N6) -> 65.68179 | R6: =IF($B6="","",VLOOKUP(I6,'2_HOJA_TECNICA'!$B$6:$K$13,9,0)) -> 18.9 | S6: =IF($B6="","",P6/R6) -> 14.142576
B7: PT-01 | C7: Vigas principales W24 nave | D7: 1250 | E7: F2 | F7: A1 | G7: R2 | H7: 2 | I7: P02 | J7: 125 | K7: NO | L7: =IF($B7="","",J7+IF(H7=1,VLOOKUP(G7,'3_FACTORES'!$B$27:$E$31,4,0),0)) -> 125 | M7: =IF($B7="","",VLOOKUP(I7,'2_HOJA_TECNICA'!$B$6:$K$13,5,0)*1000/L7) -> 6.4 | N7: =IF($B7="","",D7/M7) -> 195.3125 | O7: =IF($B7="","",1-(1-VLOOKUP(E7,'3_FACTORES'!$B$6:$D$12,3,0))*(1-VLOOKUP(F7,'3_FACTORES'!$B$17:$D$22,3,0))*(1-IF(H7>1,'3_FACTORES'!$D$36,0))*(1-'3_FACTORES'!$D$37)*(1-IF(VLOOKUP(I7,'2_HOJA_TECNICA'!$B$6:$K$13,10,0)="SI",'3_FACTORES'!$D$38,0))*(1-IF(K7="SI",'3_FACTORES'!$D$39,0))) -> 0.26128 | P7: =IF($B7="","",N7/(1-O7)) -> 264.39314 | Q7: =IF($B7="","",P7-N7) -> 69.080639 | R7: =IF($B7="","",VLOOKUP(I7,'2_HOJA_TECNICA'!$B$6:$K$13,9,0)) -> 18.9 | S7: =IF($B7="","",P7/R7) -> 13.989055
B8: PT-01 | C8: Vigas principales W24 nave | D8: 1250 | E8: F2 | F8: A1 | G8: R2 | H8: 3 | I8: P03 | J8: 75 | K8: NO | L8: =IF($B8="","",J8+IF(H8=1,VLOOKUP(G8,'3_FACTORES'!$B$27:$E$31,4,0),0)) -> 75 | M8: =IF($B8="","",VLOOKUP(I8,'2_HOJA_TECNICA'!$B$6:$K$13,5,0)*1000/L8) -> 8 | N8: =IF($B8="","",D8/M8) -> 156.25 | O8: =IF($B8="","",1-(1-VLOOKUP(E8,'3_FACTORES'!$B$6:$D$12,3,0))*(1-VLOOKUP(F8,'3_FACTORES'!$B$17:$D$22,3,0))*(1-IF(H8>1,'3_FACTORES'!$D$36,0))*(1-'3_FACTORES'!$D$37)*(1-IF(VLOOKUP(I8,'2_HOJA_TECNICA'!$B$6:$K$13,10,0)="SI",'3_FACTORES'!$D$38,0))*(1-IF(K8="SI",'3_FACTORES'!$D$39,0))) -> 0.26128 | P8: =IF($B8="","",N8/(1-O8)) -> 211.51451 | Q8: =IF($B8="","",P8-N8) -> 55.264512 | R8: =IF($B8="","",VLOOKUP(I8,'2_HOJA_TECNICA'!$B$6:$K$13,9,0)) -> 18.9 | S8: =IF($B8="","",P8/R8) -> 11.191244
B9: PT-02 | C9: Armadura de cubierta (celosía) | D9: 800 | E9: F5 | F9: A1 | G9: R2 | H9: 1 | I9: P01 | J9: 75 | K9: SI | L9: =IF($B9="","",J9+IF(H9=1,VLOOKUP(G9,'3_FACTORES'!$B$27:$E$31,4,0),0)) -> 100 | M9: =IF($B9="","",VLOOKUP(I9,'2_HOJA_TECNICA'!$B$6:$K$13,5,0)*1000/L9) -> 6.2 | N9: =IF($B9="","",D9/M9) -> 129.03226 | O9: =IF($B9="","",1-(1-VLOOKUP(E9,'3_FACTORES'!$B$6:$D$12,3,0))*(1-VLOOKUP(F9,'3_FACTORES'!$B$17:$D$22,3,0))*(1-IF(H9>1,'3_FACTORES'!$D$36,0))*(1-'3_FACTORES'!$D$37)*(1-IF(VLOOKUP(I9,'2_HOJA_TECNICA'!$B$6:$K$13,10,0)="SI",'3_FACTORES'!$D$38,0))*(1-IF(K9="SI",'3_FACTORES'!$D$39,0))) -> 0.497152 | P9: =IF($B9="","",N9/(1-O9)) -> 256.60291 | Q9: =IF($B9="","",P9-N9) -> 127.57065 | R9: =IF($B9="","",VLOOKUP(I9,'2_HOJA_TECNICA'!$B$6:$K$13,9,0)) -> 18.9 | S9: =IF($B9="","",P9/R9) -> 13.576873
B10: PT-02 | C10: Armadura de cubierta (celosía) | D10: 800 | E10: F5 | F10: A1 | G10: R2 | H10: 2 | I10: P03 | J10: 75 | K10: NO | L10: =IF($B10="","",J10+IF(H10=1,VLOOKUP(G10,'3_FACTORES'!$B$27:$E$31,4,0),0)) -> 75 | M10: =IF($B10="","",VLOOKUP(I10,'2_HOJA_TECNICA'!$B$6:$K$13,5,0)*1000/L10) -> 8 | N10: =IF($B10="","",D10/M10) -> 100 | O10: =IF($B10="","",1-(1-VLOOKUP(E10,'3_FACTORES'!$B$6:$D$12,3,0))*(1-VLOOKUP(F10,'3_FACTORES'!$B$17:$D$22,3,0))*(1-IF(H10>1,'3_FACTORES'!$D$36,0))*(1-'3_FACTORES'!$D$37)*(1-IF(VLOOKUP(I10,'2_HOJA_TECNICA'!$B$6:$K$13,10,0)="SI",'3_FACTORES'!$D$38,0))*(1-IF(K10="SI",'3_FACTORES'!$D$39,0))) -> 0.50752 | P10: =IF($B10="","",N10/(1-O10)) -> 203.05393 | Q10: =IF($B10="","",P10-N10) -> 103.05393 | R10: =IF($B10="","",VLOOKUP(I10,'2_HOJA_TECNICA'!$B$6:$K$13,9,0)) -> 18.9 | S10: =IF($B10="","",P10/R10) -> 10.743594
B11: PT-03 | C11: Columnas con protección ignífuga R60 | D11: 600 | E11: F2 | F11: A1 | G11: R4 | H11: 1 | I11: P01 | J11: 75 | K11: SI | L11: =IF($B11="","",J11+IF(H11=1,VLOOKUP(G11,'3_FACTORES'!$B$27:$E$31,4,0),0)) -> 135 | M11: =IF($B11="","",VLOOKUP(I11,'2_HOJA_TECNICA'!$B$6:$K$13,5,0)*1000/L11) -> 4.5925926 | N11: =IF($B11="","",D11/M11) -> 130.64516 | O11: =IF($B11="","",1-(1-VLOOKUP(E11,'3_FACTORES'!$B$6:$D$12,3,0))*(1-VLOOKUP(F11,'3_FACTORES'!$B$17:$D$22,3,0))*(1-IF(H11>1,'3_FACTORES'!$D$36,0))*(1-'3_FACTORES'!$D$37)*(1-IF(VLOOKUP(I11,'2_HOJA_TECNICA'!$B$6:$K$13,10,0)="SI",'3_FACTORES'!$D$38,0))*(1-IF(K11="SI",'3_FACTORES'!$D$39,0))) -> 0.245728 | P11: =IF($B11="","",N11/(1-O11)) -> 173.20696 | Q11: =IF($B11="","",P11-N11) -> 42.5618 | R11: =IF($B11="","",VLOOKUP(I11,'2_HOJA_TECNICA'!$B$6:$K$13,9,0)) -> 18.9 | S11: =IF($B11="","",P11/R11) -> 9.1643895
B12: PT-03 | C12: Columnas ignífugo R60 — INTUMESCENTE EN PLANTA | D12: 600 | E12: F2 | F12: A1 | G12: R4 | H12: 2 | I12: P04 | J12: 700 | K12: NO | L12: =IF($B12="","",J12+IF(H12=1,VLOOKUP(G12,'3_FACTORES'!$B$27:$E$31,4,0),0)) -> 700 | M12: =IF($B12="","",VLOOKUP(I12,'2_HOJA_TECNICA'!$B$6:$K$13,5,0)*1000/L12) -> 0.98571429 | N12: =IF($B12="","",D12/M12) -> 608.69565 | O12: =IF($B12="","",1-(1-VLOOKUP(E12,'3_FACTORES'!$B$6:$D$12,3,0))*(1-VLOOKUP(F12,'3_FACTORES'!$B$17:$D$22,3,0))*(1-IF(H12>1,'3_FACTORES'!$D$36,0))*(1-'3_FACTORES'!$D$37)*(1-IF(VLOOKUP(I12,'2_HOJA_TECNICA'!$B$6:$K$13,10,0)="SI",'3_FACTORES'!$D$38,0))*(1-IF(K12="SI",'3_FACTORES'!$D$39,0))) -> 0.3499264 | P12: =IF($B12="","",N12/(1-O12)) -> 936.34883 | Q12: =IF($B12="","",P12-N12) -> 327.65317 | R12: =IF($B12="","",VLOOKUP(I12,'2_HOJA_TECNICA'!$B$6:$K$13,9,0)) -> 25 | S12: =IF($B12="","",P12/R12) -> 37.453953
B13: PT-03 | C13: Columnas ignífugo R60 — INTUMESCENTE EN SITIO | D13: 600 | E13: F2 | F13: A6 | G13: R4 | H13: 3 | I13: P04 | J13: 300 | K13: NO | L13: =IF($B13="","",J13+IF(H13=1,VLOOKUP(G13,'3_FACTORES'!$B$27:$E$31,4,0),0)) -> 300 | M13: =IF($B13="","",VLOOKUP(I13,'2_HOJA_TECNICA'!$B$6:$K$13,5,0)*1000/L13) -> 2.3 | N13: =IF($B13="","",D13/M13) -> 260.86957 | O13: =IF($B13="","",1-(1-VLOOKUP(E13,'3_FACTORES'!$B$6:$D$12,3,0))*(1-VLOOKUP(F13,'3_FACTORES'!$B$17:$D$22,3,0))*(1-IF(H13>1,'3_FACTORES'!$D$36,0))*(1-'3_FACTORES'!$D$37)*(1-IF(VLOOKUP(I13,'2_HOJA_TECNICA'!$B$6:$K$13,10,0)="SI",'3_FACTORES'!$D$38,0))*(1-IF(K13="SI",'3_FACTORES'!$D$39,0))) -> 0.33548032 | P13: =IF($B13="","",N13/(1-O13)) -> 392.56861 | Q13: =IF($B13="","",P13-N13) -> 131.69904 | R13: =IF($B13="","",VLOOKUP(I13,'2_HOJA_TECNICA'!$B$6:$K$13,9,0)) -> 25 | S13: =IF($B13="","",P13/R13) -> 15.702744
L14: =IF($B14="","",J14+IF(H14=1,VLOOKUP(G14,'3_FACTORES'!$B$27:$E$31,4,0),0)) | M14: =IF($B14="","",VLOOKUP(I14,'2_HOJA_TECNICA'!$B$6:$K$13,5,0)*1000/L14) | N14: =IF($B14="","",D14/M14) | O14: =IF($B14="","",1-(1-VLOOKUP(E14,'3_FACTORES'!$B$6:$D$12,3,0))*(1-VLOOKUP(F14,'3_FACTORES'!$B$17:$D$22,3,0))*(1-IF(H14>1,'3_FACTORES'!$D$36,0))*(1-'3_FACTORES'!$D$37)*(1-IF(VLOOKUP(I14,'2_HOJA_TECNICA'!$B$6:$K$13,10,0)="SI",'3_FACTORES'!$D$38,0))*(1-IF(K14="SI",'3_FACTORES'!$D$39,0))) | P14: =IF($B14="","",N14/(1-O14)) | Q14: =IF($B14="","",P14-N14) | R14: =IF($B14="","",VLOOKUP(I14,'2_HOJA_TECNICA'!$B$6:$K$13,9,0)) | S14: =IF($B14="","",P14/R14)
L15: =IF($B15="","",J15+IF(H15=1,VLOOKUP(G15,'3_FACTORES'!$B$27:$E$31,4,0),0)) | M15: =IF($B15="","",VLOOKUP(I15,'2_HOJA_TECNICA'!$B$6:$K$13,5,0)*1000/L15) | N15: =IF($B15="","",D15/M15) | O15: =IF($B15="","",1-(1-VLOOKUP(E15,'3_FACTORES'!$B$6:$D$12,3,0))*(1-VLOOKUP(F15,'3_FACTORES'!$B$17:$D$22,3,0))*(1-IF(H15>1,'3_FACTORES'!$D$36,0))*(1-'3_FACTORES'!$D$37)*(1-IF(VLOOKUP(I15,'2_HOJA_TECNICA'!$B$6:$K$13,10,0)="SI",'3_FACTORES'!$D$38,0))*(1-IF(K15="SI",'3_FACTORES'!$D$39,0))) | P15: =IF($B15="","",N15/(1-O15)) | Q15: =IF($B15="","",P15-N15) | R15: =IF($B15="","",VLOOKUP(I15,'2_HOJA_TECNICA'!$B$6:$K$13,9,0)) | S15: =IF($B15="","",P15/R15)
L16: =IF($B16="","",J16+IF(H16=1,VLOOKUP(G16,'3_FACTORES'!$B$27:$E$31,4,0),0)) | M16: =IF($B16="","",VLOOKUP(I16,'2_HOJA_TECNICA'!$B$6:$K$13,5,0)*1000/L16) | N16: =IF($B16="","",D16/M16) | O16: =IF($B16="","",1-(1-VLOOKUP(E16,'3_FACTORES'!$B$6:$D$12,3,0))*(1-VLOOKUP(F16,'3_FACTORES'!$B$17:$D$22,3,0))*(1-IF(H16>1,'3_FACTORES'!$D$36,0))*(1-'3_FACTORES'!$D$37)*(1-IF(VLOOKUP(I16,'2_HOJA_TECNICA'!$B$6:$K$13,10,0)="SI",'3_FACTORES'!$D$38,0))*(1-IF(K16="SI",'3_FACTORES'!$D$39,0))) | P16: =IF($B16="","",N16/(1-O16)) | Q16: =IF($B16="","",P16-N16) | R16: =IF($B16="","",VLOOKUP(I16,'2_HOJA_TECNICA'!$B$6:$K$13,9,0)) | S16: =IF($B16="","",P16/R16)
L17: =IF($B17="","",J17+IF(H17=1,VLOOKUP(G17,'3_FACTORES'!$B$27:$E$31,4,0),0)) | M17: =IF($B17="","",VLOOKUP(I17,'2_HOJA_TECNICA'!$B$6:$K$13,5,0)*1000/L17) | N17: =IF($B17="","",D17/M17) | O17: =IF($B17="","",1-(1-VLOOKUP(E17,'3_FACTORES'!$B$6:$D$12,3,0))*(1-VLOOKUP(F17,'3_FACTORES'!$B$17:$D$22,3,0))*(1-IF(H17>1,'3_FACTORES'!$D$36,0))*(1-'3_FACTORES'!$D$37)*(1-IF(VLOOKUP(I17,'2_HOJA_TECNICA'!$B$6:$K$13,10,0)="SI",'3_FACTORES'!$D$38,0))*(1-IF(K17="SI",'3_FACTORES'!$D$39,0))) | P17: =IF($B17="","",N17/(1-O17)) | Q17: =IF($B17="","",P17-N17) | R17: =IF($B17="","",VLOOKUP(I17,'2_HOJA_TECNICA'!$B$6:$K$13,9,0)) | S17: =IF($B17="","",P17/R17)
L18: =IF($B18="","",J18+IF(H18=1,VLOOKUP(G18,'3_FACTORES'!$B$27:$E$31,4,0),0)) | M18: =IF($B18="","",VLOOKUP(I18,'2_HOJA_TECNICA'!$B$6:$K$13,5,0)*1000/L18) | N18: =IF($B18="","",D18/M18) | O18: =IF($B18="","",1-(1-VLOOKUP(E18,'3_FACTORES'!$B$6:$D$12,3,0))*(1-VLOOKUP(F18,'3_FACTORES'!$B$17:$D$22,3,0))*(1-IF(H18>1,'3_FACTORES'!$D$36,0))*(1-'3_FACTORES'!$D$37)*(1-IF(VLOOKUP(I18,'2_HOJA_TECNICA'!$B$6:$K$13,10,0)="SI",'3_FACTORES'!$D$38,0))*(1-IF(K18="SI",'3_FACTORES'!$D$39,0))) | P18: =IF($B18="","",N18/(1-O18)) | Q18: =IF($B18="","",P18-N18) | R18: =IF($B18="","",VLOOKUP(I18,'2_HOJA_TECNICA'!$B$6:$K$13,9,0)) | S18: =IF($B18="","",P18/R18)
L19: =IF($B19="","",J19+IF(H19=1,VLOOKUP(G19,'3_FACTORES'!$B$27:$E$31,4,0),0)) | M19: =IF($B19="","",VLOOKUP(I19,'2_HOJA_TECNICA'!$B$6:$K$13,5,0)*1000/L19) | N19: =IF($B19="","",D19/M19) | O19: =IF($B19="","",1-(1-VLOOKUP(E19,'3_FACTORES'!$B$6:$D$12,3,0))*(1-VLOOKUP(F19,'3_FACTORES'!$B$17:$D$22,3,0))*(1-IF(H19>1,'3_FACTORES'!$D$36,0))*(1-'3_FACTORES'!$D$37)*(1-IF(VLOOKUP(I19,'2_HOJA_TECNICA'!$B$6:$K$13,10,0)="SI",'3_FACTORES'!$D$38,0))*(1-IF(K19="SI",'3_FACTORES'!$D$39,0))) | P19: =IF($B19="","",N19/(1-O19)) | Q19: =IF($B19="","",P19-N19) | R19: =IF($B19="","",VLOOKUP(I19,'2_HOJA_TECNICA'!$B$6:$K$13,9,0)) | S19: =IF($B19="","",P19/R19)
L20: =IF($B20="","",J20+IF(H20=1,VLOOKUP(G20,'3_FACTORES'!$B$27:$E$31,4,0),0)) | M20: =IF($B20="","",VLOOKUP(I20,'2_HOJA_TECNICA'!$B$6:$K$13,5,0)*1000/L20) | N20: =IF($B20="","",D20/M20) | O20: =IF($B20="","",1-(1-VLOOKUP(E20,'3_FACTORES'!$B$6:$D$12,3,0))*(1-VLOOKUP(F20,'3_FACTORES'!$B$17:$D$22,3,0))*(1-IF(H20>1,'3_FACTORES'!$D$36,0))*(1-'3_FACTORES'!$D$37)*(1-IF(VLOOKUP(I20,'2_HOJA_TECNICA'!$B$6:$K$13,10,0)="SI",'3_FACTORES'!$D$38,0))*(1-IF(K20="SI",'3_FACTORES'!$D$39,0))) | P20: =IF($B20="","",N20/(1-O20)) | Q20: =IF($B20="","",P20-N20) | R20: =IF($B20="","",VLOOKUP(I20,'2_HOJA_TECNICA'!$B$6:$K$13,9,0)) | S20: =IF($B20="","",P20/R20)
L21: =IF($B21="","",J21+IF(H21=1,VLOOKUP(G21,'3_FACTORES'!$B$27:$E$31,4,0),0)) | M21: =IF($B21="","",VLOOKUP(I21,'2_HOJA_TECNICA'!$B$6:$K$13,5,0)*1000/L21) | N21: =IF($B21="","",D21/M21) | O21: =IF($B21="","",1-(1-VLOOKUP(E21,'3_FACTORES'!$B$6:$D$12,3,0))*(1-VLOOKUP(F21,'3_FACTORES'!$B$17:$D$22,3,0))*(1-IF(H21>1,'3_FACTORES'!$D$36,0))*(1-'3_FACTORES'!$D$37)*(1-IF(VLOOKUP(I21,'2_HOJA_TECNICA'!$B$6:$K$13,10,0)="SI",'3_FACTORES'!$D$38,0))*(1-IF(K21="SI",'3_FACTORES'!$D$39,0))) | P21: =IF($B21="","",N21/(1-O21)) | Q21: =IF($B21="","",P21-N21) | R21: =IF($B21="","",VLOOKUP(I21,'2_HOJA_TECNICA'!$B$6:$K$13,9,0)) | S21: =IF($B21="","",P21/R21)
L22: =IF($B22="","",J22+IF(H22=1,VLOOKUP(G22,'3_FACTORES'!$B$27:$E$31,4,0),0)) | M22: =IF($B22="","",VLOOKUP(I22,'2_HOJA_TECNICA'!$B$6:$K$13,5,0)*1000/L22) | N22: =IF($B22="","",D22/M22) | O22: =IF($B22="","",1-(1-VLOOKUP(E22,'3_FACTORES'!$B$6:$D$12,3,0))*(1-VLOOKUP(F22,'3_FACTORES'!$B$17:$D$22,3,0))*(1-IF(H22>1,'3_FACTORES'!$D$36,0))*(1-'3_FACTORES'!$D$37)*(1-IF(VLOOKUP(I22,'2_HOJA_TECNICA'!$B$6:$K$13,10,0)="SI",'3_FACTORES'!$D$38,0))*(1-IF(K22="SI",'3_FACTORES'!$D$39,0))) | P22: =IF($B22="","",N22/(1-O22)) | Q22: =IF($B22="","",P22-N22) | R22: =IF($B22="","",VLOOKUP(I22,'2_HOJA_TECNICA'!$B$6:$K$13,9,0)) | S22: =IF($B22="","",P22/R22)
L23: =IF($B23="","",J23+IF(H23=1,VLOOKUP(G23,'3_FACTORES'!$B$27:$E$31,4,0),0)) | M23: =IF($B23="","",VLOOKUP(I23,'2_HOJA_TECNICA'!$B$6:$K$13,5,0)*1000/L23) | N23: =IF($B23="","",D23/M23) | O23: =IF($B23="","",1-(1-VLOOKUP(E23,'3_FACTORES'!$B$6:$D$12,3,0))*(1-VLOOKUP(F23,'3_FACTORES'!$B$17:$D$22,3,0))*(1-IF(H23>1,'3_FACTORES'!$D$36,0))*(1-'3_FACTORES'!$D$37)*(1-IF(VLOOKUP(I23,'2_HOJA_TECNICA'!$B$6:$K$13,10,0)="SI",'3_FACTORES'!$D$38,0))*(1-IF(K23="SI",'3_FACTORES'!$D$39,0))) | P23: =IF($B23="","",N23/(1-O23)) | Q23: =IF($B23="","",P23-N23) | R23: =IF($B23="","",VLOOKUP(I23,'2_HOJA_TECNICA'!$B$6:$K$13,9,0)) | S23: =IF($B23="","",P23/R23)
L24: =IF($B24="","",J24+IF(H24=1,VLOOKUP(G24,'3_FACTORES'!$B$27:$E$31,4,0),0)) | M24: =IF($B24="","",VLOOKUP(I24,'2_HOJA_TECNICA'!$B$6:$K$13,5,0)*1000/L24) | N24: =IF($B24="","",D24/M24) | O24: =IF($B24="","",1-(1-VLOOKUP(E24,'3_FACTORES'!$B$6:$D$12,3,0))*(1-VLOOKUP(F24,'3_FACTORES'!$B$17:$D$22,3,0))*(1-IF(H24>1,'3_FACTORES'!$D$36,0))*(1-'3_FACTORES'!$D$37)*(1-IF(VLOOKUP(I24,'2_HOJA_TECNICA'!$B$6:$K$13,10,0)="SI",'3_FACTORES'!$D$38,0))*(1-IF(K24="SI",'3_FACTORES'!$D$39,0))) | P24: =IF($B24="","",N24/(1-O24)) | Q24: =IF($B24="","",P24-N24) | R24: =IF($B24="","",VLOOKUP(I24,'2_HOJA_TECNICA'!$B$6:$K$13,9,0)) | S24: =IF($B24="","",P24/R24)
L25: =IF($B25="","",J25+IF(H25=1,VLOOKUP(G25,'3_FACTORES'!$B$27:$E$31,4,0),0)) | M25: =IF($B25="","",VLOOKUP(I25,'2_HOJA_TECNICA'!$B$6:$K$13,5,0)*1000/L25) | N25: =IF($B25="","",D25/M25) | O25: =IF($B25="","",1-(1-VLOOKUP(E25,'3_FACTORES'!$B$6:$D$12,3,0))*(1-VLOOKUP(F25,'3_FACTORES'!$B$17:$D$22,3,0))*(1-IF(H25>1,'3_FACTORES'!$D$36,0))*(1-'3_FACTORES'!$D$37)*(1-IF(VLOOKUP(I25,'2_HOJA_TECNICA'!$B$6:$K$13,10,0)="SI",'3_FACTORES'!$D$38,0))*(1-IF(K25="SI",'3_FACTORES'!$D$39,0))) | P25: =IF($B25="","",N25/(1-O25)) | Q25: =IF($B25="","",P25-N25) | R25: =IF($B25="","",VLOOKUP(I25,'2_HOJA_TECNICA'!$B$6:$K$13,9,0)) | S25: =IF($B25="","",P25/R25)
C26: TOTALES | N26: =SUM(N6:N25) -> 1782.418 | P26: =SUM(P6:P25) -> 2704.9836 | Q26: =SUM(Q6:Q25) -> 922.56554

Sheet 5_RESUMEN
B2: RESUMEN DE COMPRA POR PRODUCTO — CUÑETES Y DESPERDICIO
B3: Consolida 4_CALCULO por producto. La compra se redondea a cuñetes completos; el "colchón de compra" es el excedente por redondeo.
B5: ID Prod. | C5: Producto | D5: Litros teóricos | E5: Litros prácticos | F5: Litros desperdicio | G5: % Desp. medio | H5: Cuñete (L) | I5: Cuñetes a comprar | J5: Litros comprados | K5: Colchón redondeo (L) | L5: Costo compra ($)
B6: ='2_HOJA_TECNICA'!B6 -> P01 | C6: =IF(B6="","",'2_HOJA_TECNICA'!C6) -> Primario epóxico rico en zinc | D6: =IF($B6="","",SUMIF('4_CALCULO'!$I$6:$I$25,$B6,'4_CALCULO'!$N$6:$N$25)) -> 461.29032 | E6: =IF($B6="","",SUMIF('4_CALCULO'!$I$6:$I$25,$B6,'4_CALCULO'!$P$6:$P$25)) -> 697.10456 | F6: =IF($B6="","",SUMIF('4_CALCULO'!$I$6:$I$25,$B6,'4_CALCULO'!$Q$6:$Q$25)) -> 235.81424 | G6: =IF(OR($B6="",E6=0),"",F6/E6) -> 0.33827671 | H6: =IF($B6="","",'2_HOJA_TECNICA'!J6) -> 18.9 | I6: =IF(OR($B6="",E6=0),"",ROUNDUP(E6/H6,0)) -> 37 | J6: =IF($B6="","",IF(I6="","",I6*H6)) -> 699.3 | K6: =IF(OR($B6="",I6=""),"",J6-E6) -> 2.1954388 | L6: =IF(OR($B6="",I6=""),"",I6*'2_HOJA_TECNICA'!L6) -> 0
B7: ='2_HOJA_TECNICA'!B7 -> P02 | C7: =IF(B7="","",'2_HOJA_TECNICA'!C7) -> Epóxico poliamida alto sólidos | D7: =IF($B7="","",SUMIF('4_CALCULO'!$I$6:$I$25,$B7,'4_CALCULO'!$N$6:$N$25)) -> 195.3125 | E7: =IF($B7="","",SUMIF('4_CALCULO'!$I$6:$I$25,$B7,'4_CALCULO'!$P$6:$P$25)) -> 264.39314 | F7: =IF($B7="","",SUMIF('4_CALCULO'!$I$6:$I$25,$B7,'4_CALCULO'!$Q$6:$Q$25)) -> 69.080639 | G7: =IF(OR($B7="",E7=0),"",F7/E7) -> 0.26128 | H7: =IF($B7="","",'2_HOJA_TECNICA'!J7) -> 18.9 | I7: =IF(OR($B7="",E7=0),"",ROUNDUP(E7/H7,0)) -> 14 | J7: =IF($B7="","",IF(I7="","",I7*H7)) -> 264.6 | K7: =IF(OR($B7="",I7=""),"",J7-E7) -> 0.20686052 | L7: =IF(OR($B7="",I7=""),"",I7*'2_HOJA_TECNICA'!L7) -> 0
B8: ='2_HOJA_TECNICA'!B8 -> P03 | C8: =IF(B8="","",'2_HOJA_TECNICA'!C8) -> Acabado poliuretano alifático | D8: =IF($B8="","",SUMIF('4_CALCULO'!$I$6:$I$25,$B8,'4_CALCULO'!$N$6:$N$25)) -> 256.25 | E8: =IF($B8="","",SUMIF('4_CALCULO'!$I$6:$I$25,$B8,'4_CALCULO'!$P$6:$P$25)) -> 414.56844 | F8: =IF($B8="","",SUMIF('4_CALCULO'!$I$6:$I$25,$B8,'4_CALCULO'!$Q$6:$Q$25)) -> 158.31844 | G8: =IF(OR($B8="",E8=0),"",F8/E8) -> 0.38188735 | H8: =IF($B8="","",'2_HOJA_TECNICA'!J8) -> 18.9 | I8: =IF(OR($B8="",E8=0),"",ROUNDUP(E8/H8,0)) -> 22 | J8: =IF($B8="","",IF(I8="","",I8*H8)) -> 415.8 | K8: =IF(OR($B8="",I8=""),"",J8-E8) -> 1.2315573 | L8: =IF(OR($B8="",I8=""),"",I8*'2_HOJA_TECNICA'!L8) -> 0
B9: ='2_HOJA_TECNICA'!B9 -> P04 | C9: =IF(B9="","",'2_HOJA_TECNICA'!C9) -> Intumescente base agua | D9: =IF($B9="","",SUMIF('4_CALCULO'!$I$6:$I$25,$B9,'4_CALCULO'!$N$6:$N$25)) -> 869.56522 | E9: =IF($B9="","",SUMIF('4_CALCULO'!$I$6:$I$25,$B9,'4_CALCULO'!$P$6:$P$25)) -> 1328.9174 | F9: =IF($B9="","",SUMIF('4_CALCULO'!$I$6:$I$25,$B9,'4_CALCULO'!$Q$6:$Q$25)) -> 459.35222 | G9: =IF(OR($B9="",E9=0),"",F9/E9) -> 0.34565896 | H9: =IF($B9="","",'2_HOJA_TECNICA'!J9) -> 25 | I9: =IF(OR($B9="",E9=0),"",ROUNDUP(E9/H9,0)) -> 54 | J9: =IF($B9="","",IF(I9="","",I9*H9)) -> 1350 | K9: =IF(OR($B9="",I9=""),"",J9-E9) -> 21.082567 | L9: =IF(OR($B9="",I9=""),"",I9*'2_HOJA_TECNICA'!L9) -> 0
B10: ='2_HOJA_TECNICA'!B10 -> P05 | C10: =IF(B10="","",'2_HOJA_TECNICA'!C10) -> 0 | D10: =IF($B10="","",SUMIF('4_CALCULO'!$I$6:$I$25,$B10,'4_CALCULO'!$N$6:$N$25)) -> 0 | E10: =IF($B10="","",SUMIF('4_CALCULO'!$I$6:$I$25,$B10,'4_CALCULO'!$P$6:$P$25)) -> 0 | F10: =IF($B10="","",SUMIF('4_CALCULO'!$I$6:$I$25,$B10,'4_CALCULO'!$Q$6:$Q$25)) -> 0 | G10: =IF(OR($B10="",E10=0),"",F10/E10) | H10: =IF($B10="","",'2_HOJA_TECNICA'!J10) -> 0 | I10: =IF(OR($B10="",E10=0),"",ROUNDUP(E10/H10,0)) | J10: =IF($B10="","",IF(I10="","",I10*H10)) | K10: =IF(OR($B10="",I10=""),"",J10-E10) | L10: =IF(OR($B10="",I10=""),"",I10*'2_HOJA_TECNICA'!L10)
B11: ='2_HOJA_TECNICA'!B11 -> P06 | C11: =IF(B11="","",'2_HOJA_TECNICA'!C11) -> 0 | D11: =IF($B11="","",SUMIF('4_CALCULO'!$I$6:$I$25,$B11,'4_CALCULO'!$N$6:$N$25)) -> 0 | E11: =IF($B11="","",SUMIF('4_CALCULO'!$I$6:$I$25,$B11,'4_CALCULO'!$P$6:$P$25)) -> 0 | F11: =IF($B11="","",SUMIF('4_CALCULO'!$I$6:$I$25,$B11,'4_CALCULO'!$Q$6:$Q$25)) -> 0 | G11: =IF(OR($B11="",E11=0),"",F11/E11) | H11: =IF($B11="","",'2_HOJA_TECNICA'!J11) -> 0 | I11: =IF(OR($B11="",E11=0),"",ROUNDUP(E11/H11,0)) | J11: =IF($B11="","",IF(I11="","",I11*H11)) | K11: =IF(OR($B11="",I11=""),"",J11-E11) | L11: =IF(OR($B11="",I11=""),"",I11*'2_HOJA_TECNICA'!L11)
B12: ='2_HOJA_TECNICA'!B12 -> P07 | C12: =IF(B12="","",'2_HOJA_TECNICA'!C12) -> 0 | D12: =IF($B12="","",SUMIF('4_CALCULO'!$I$6:$I$25,$B12,'4_CALCULO'!$N$6:$N$25)) -> 0 | E12: =IF($B12="","",SUMIF('4_CALCULO'!$I$6:$I$25,$B12,'4_CALCULO'!$P$6:$P$25)) -> 0 | F12: =IF($B12="","",SUMIF('4_CALCULO'!$I$6:$I$25,$B12,'4_CALCULO'!$Q$6:$Q$25)) -> 0 | G12: =IF(OR($B12="",E12=0),"",F12/E12) | H12: =IF($B12="","",'2_HOJA_TECNICA'!J12) -> 0 | I12: =IF(OR($B12="",E12=0),"",ROUNDUP(E12/H12,0)) | J12: =IF($B12="","",IF(I12="","",I12*H12)) | K12: =IF(OR($B12="",I12=""),"",J12-E12) | L12: =IF(OR($B12="",I12=""),"",I12*'2_HOJA_TECNICA'!L12)
B13: ='2_HOJA_TECNICA'!B13 -> P08 | C13: =IF(B13="","",'2_HOJA_TECNICA'!C13) -> 0 | D13: =IF($B13="","",SUMIF('4_CALCULO'!$I$6:$I$25,$B13,'4_CALCULO'!$N$6:$N$25)) -> 0 | E13: =IF($B13="","",SUMIF('4_CALCULO'!$I$6:$I$25,$B13,'4_CALCULO'!$P$6:$P$25)) -> 0 | F13: =IF($B13="","",SUMIF('4_CALCULO'!$I$6:$I$25,$B13,'4_CALCULO'!$Q$6:$Q$25)) -> 0 | G13: =IF(OR($B13="",E13=0),"",F13/E13) | H13: =IF($B13="","",'2_HOJA_TECNICA'!J13) -> 0 | I13: =IF(OR($B13="",E13=0),"",ROUNDUP(E13/H13,0)) | J13: =IF($B13="","",IF(I13="","",I13*H13)) | K13: =IF(OR($B13="",I13=""),"",J13-E13) | L13: =IF(OR($B13="",I13=""),"",I13*'2_HOJA_TECNICA'!L13)
C14: TOTAL | D14: =SUM(D6:D13) -> 1782.418 | E14: =SUM(E6:E13) -> 2704.9836 | F14: =SUM(F6:F13) -> 922.56554 | I14: =SUM(I6:I13) -> 127 | J14: =SUM(J6:J13) -> 2729.7 | K14: =SUM(K6:K13) -> 24.716423 | L14: =SUM(L6:L13) -> 0

Sheet 6_IGNIFUGO
B2: PINTURA INTUMESCENTE — GUÍA DE MASIVIDAD Hp/A Y CONSIDERACIONES
B4: TABLA ILUSTRATIVA — EPS (µm) según masividad Hp/A y resistencia al fuego (SUSTITUIR por certificado del fabricante)
B5: Hp/A (m⁻¹) | C5: R30 (µm) | D5: R60 (µm) | E5: R90 (µm) | F5: R120 (µm) | G5: Comentario
B6: 50 | C6: 250 | D6: 450 | E6: 900 | F6: 1500 | G6: Secciones muy pesadas: espesores mínimos.
B7: 100 | C7: 300 | D7: 700 | E7: 1400 | F7: 2400 | G7: Rango común de columnas W pesadas.
B8: 150 | C8: 400 | D8: 1000 | E8: 2000 | F8: 3400 | G8: Vigas y columnas medianas.
B9: 200 | C9: 500 | D9: 1300 | E9: 2700 | F9: 4500 | G9: Perfiles ligeros: espesores altos; evaluar mortero proyectado como alternativa.
B10: 260 | C10: 650 | D10: 1700 | E10: 3500 | F10: 6000 | G10: Límite práctico usual de perfiles a proteger con intumescente.
B13: CALCULADORA DE MASIVIDAD Hp/A
B14: Perímetro expuesto Hp (m): | C14: 1.6 | D14: 3 caras o 4 caras según condición de exposición (losa sobre patín superior = 3 caras).
B15: Área de la sección A (m²): | C15: 0.0119
B16: Hp/A (m⁻¹): | C16: =IF(C15=0,"",C14/C15) -> 134.45378
B18: CONSIDERACIONES OBLIGATORIAS PARA INTUMESCENTES
B19: EPS certificado | C19: El espesor NO sale del TDS genérico: sale de la carta de espesores certificada del fabricante (UL 263 / ASTM E119 / EN 13381-8) para el Hp/A de cada perfil y el tiempo R requerido. Zona Humana: validar contra certificado y proyecto.
B20: Primario compatible | C20: Solo primarios aprobados por el fabricante del intumescente (normalmente epóxico o zinc aprobado, 50–75 µm). Un primario no certificado invalida la protección.
B21: Múltiples pasadas | C21: Espesor máximo por pasada típico 400–800 µm húmedo (base agua) — un R60 puede requerir 3–6 pasadas con secado entre ellas. Cada pasada suma pérdidas: por eso la Tabla D aplica el recargo D3.
B22: Ambiente de aplicación | C22: Base agua: aplicar en taller o ambiente controlado (T > 10 °C, HR < 80%, sustrato 3 °C sobre punto de rocío). Exterior sin control = riesgo de lavado por lluvia antes de curar.
B23: Sellador / top coat | C23: En exposición exterior o C3+, el intumescente requiere sello de acabado aprobado; incluirlo como capa adicional en 4_CALCULO.
B24: Densidad y rendimiento | C24: Los intumescentes rinden poco (SV 65–72%, EPS enormes): 1 m² a 1,000 µm consume ≈1.4–1.5 L teóricos. El costo por m² domina el APU: cotizar por Hp/A real, nunca con EPS promedio.
B25: Medición y trazabilidad | C25: Registrar EPS por pasada (SSPC-PA 2 nivel por elemento); el cliente/DRO exige el registro para liberar. Reproceso por espesor bajo = más consumo no presupuestado si no se controla.
B26: Malla de refuerzo | C26: Espesores > ~3,000 µm o secciones críticas pueden requerir malla de refuerzo según fabricante: costo y HH adicionales fuera de este módulo.
B28: REPARTO PLANTA / SITIO DEL INTUMESCENTE (asistente de captura)
B29: El intumescente casi nunca se termina en planta: lo usual es aplicar el grueso del espesor en taller (ambiente controlado, mejor rendimiento) y completar en sitio las últimas manos, los retoques de montaje y las zonas de conexión. Capture aquí el reparto y el asistente le da el EPS de cada porción; luego capture DOS filas en 4_CALCULO para la misma partida: la porción PLANTA con ambiente A1 y la porción SITIO con ambiente A4 o A6. El modelo aplicará automáticamente el mayor desperdicio de obra (viento, condiciones, brocha) y el APU puede cargar la HH de obra más alta. El ejemplo PT-03 de 4_CALCULO ya está capturado así.
B31: EPS total requerido (µm): | C31: 1000 | D31: Reparto típico: 60–80% en planta. Deje más al sitio si habrá mucho daño de transporte/montaje o si las conexiones son de campo.
B32: % del EPS aplicado en PLANTA: | C32: 0.7
B33: EPS a capturar como fila PLANTA (A1): | C33: =C31*C32 -> 700
B34: EPS a capturar como fila SITIO (A4/A6): | C34: =C31*(1-C32) -> 300
B36: Rendimientos distintos planta vs. obra (para el APU): el mismo aplicador rinde en obra entre 40% y 60% de lo que rinde en planta (andamios, clima, logística de materiales, esperas de secado a la intemperie). Capture la partida de sitio con HH/m² propia en 11_APU o cargue la diferencia como partida separada. La pintura también rinde menos: eso ya lo captura el ambiente A4/A6 en la fila de sitio.

Sheet 7_ABRASIVO
B2: CONSUMO DE ABRASIVO — ARENA (SANDBLASTING) Y GRANALLA (SHOT BLASTING)
B3: La arena es de UN SOLO USO (a cielo abierto no se recupera; se contamina y fragmenta). La granalla de acero RECIRCULA en máquina o cuarto de recuperación: el consumo neto es solo la merma por atrición, fugas y limpieza. Calibre los valores en amarillo con datos de planta.
B5: TABLA E — PARÁMETROS DEL ABRASIVO (consumo bruto por grado de limpieza + desperdicio más probable)
B6: Código | C6: Abrasivo / Sistema | E6: Consumo SP6 (kg/m²) | F6: Consumo SP10 (kg/m²) | G6: Consumo SP5 (kg/m²) | H6: % Desperdicio probable | I6: Presentación (kg) | J6: Precio ($/presentación) | N6: Criterio
B7: AB1 | C7: Arena sílica / mineral — sandblasting a cielo abierto | E7: 30 | F7: 45 | G7: 55 | H7: 0.15 | I7: 1500 | J7: 0 | N7: Un solo uso. El consumo bruto ya incluye que no se recupera; el desperdicio adicional (15%) cubre humedad, derrames, fondo de sacos/súper sacos y arena no aprovechable del lote. Perfil obtenido más irregular. Restricciones de sílice libre (NOM-010-STPS): considerar escoria de cobre/níquel como sustituto con consumos similares.
B8: AB2 | C8: Granalla de acero (shot/grit) — máquina de granallado con recuperación | E8: 0.35 | F8: 0.55 | G8: 0.75 | H8: 0.08 | I8: 25 | J8: 0 | N8: Recircula 150–250 ciclos: el consumo neto es la REPOSICIÓN por atrición (desgaste del grano) + finos extraídos por el separador. El desperdicio adicional (8%) cubre fugas de sellos, granalla atrapada en cajones/perfiles tubulares que se va con la pieza, derrames y purgas de mezcla operativa.
B9: AB3 | C9: Granalla de acero — cuarto de blasteo manual con recuperación parcial | E9: 1.2 | F9: 1.8 | G9: 2.4 | H9: 0.2 | I9: 25 | J9: 0 | N9: Recuperación por barrido/tornillo sinfín menos eficiente que máquina: más pérdida por mezcla con óxido/cascarilla y granalla que sale en las piezas. Desperdicio 20% sobre la reposición.
B10: Presentación: arena en súper saco (1,500 kg típico) o granel; granalla en saco de 25 kg. Ajuste según su proveedor. Los consumos por m² dependen de la condición inicial del acero (grado de oxidación A–D según ISO 8501-1): los valores precargados asumen condición B–C típica de perfil comercial.
B12: CÁLCULO DE ABRASIVO POR PARTIDA
B13: Partida | C13: Descripción | D13: Área (m²) | E13: Abrasivo (AB1-AB3) | F13: Grado limpieza (SP6/SP10/SP5) | G13: Consumo base (kg/m²) | H13: Kg teóricos | I13: % Desperdicio | J13: Kg totales | K13: Presentación (kg) | L13: Presentaciones a comprar | M13: Kg comprados | N13: Costo ($) | O13: Condición (A-D)
B14: PT-01 | C14: Vigas principales W24 nave | D14: 1250 | E14: AB2 | F14: SP10 | G14: =IF($B14="","",VLOOKUP(E14,$B$7:$J$9,IF(F14="SP6",4,IF(F14="SP10",5,6)),0)*IF(O14="",1,VLOOKUP(O14,$B$33:$E$36,4,0))) -> 0.55 | H14: =IF($B14="","",D14*G14) -> 687.5 | I14: =IF($B14="","",VLOOKUP(E14,$B$7:$J$9,7,0)) -> 0.08 | J14: =IF($B14="","",H14*(1+I14)) -> 742.5 | K14: =IF($B14="","",VLOOKUP(E14,$B$7:$J$9,8,0)) -> 25 | L14: =IF($B14="","",ROUNDUP(J14/K14,0)) -> 30 | M14: =IF($B14="","",L14*K14) -> 750 | N14: =IF($B14="","",L14*VLOOKUP(E14,$B$7:$J$9,9,0)) -> 0 | O14: B
B15: PT-02 | C15: Armadura de cubierta (celosía) | D15: 800 | E15: AB3 | F15: SP10 | G15: =IF($B15="","",VLOOKUP(E15,$B$7:$J$9,IF(F15="SP6",4,IF(F15="SP10",5,6)),0)*IF(O15="",1,VLOOKUP(O15,$B$33:$E$36,4,0))) -> 2.52 | H15: =IF($B15="","",D15*G15) -> 2016 | I15: =IF($B15="","",VLOOKUP(E15,$B$7:$J$9,7,0)) -> 0.2 | J15: =IF($B15="","",H15*(1+I15)) -> 2419.2 | K15: =IF($B15="","",VLOOKUP(E15,$B$7:$J$9,8,0)) -> 25 | L15: =IF($B15="","",ROUNDUP(J15/K15,0)) -> 97 | M15: =IF($B15="","",L15*K15) -> 2425 | N15: =IF($B15="","",L15*VLOOKUP(E15,$B$7:$J$9,9,0)) -> 0 | O15: C
B16: PT-03 | C16: Columnas con protección ignífuga R60 | D16: 600 | E16: AB2 | F16: SP10 | G16: =IF($B16="","",VLOOKUP(E16,$B$7:$J$9,IF(F16="SP6",4,IF(F16="SP10",5,6)),0)*IF(O16="",1,VLOOKUP(O16,$B$33:$E$36,4,0))) -> 0.715 | H16: =IF($B16="","",D16*G16) -> 429 | I16: =IF($B16="","",VLOOKUP(E16,$B$7:$J$9,7,0)) -> 0.08 | J16: =IF($B16="","",H16*(1+I16)) -> 463.32 | K16: =IF($B16="","",VLOOKUP(E16,$B$7:$J$9,8,0)) -> 25 | L16: =IF($B16="","",ROUNDUP(J16/K16,0)) -> 19 | M16: =IF($B16="","",L16*K16) -> 475 | N16: =IF($B16="","",L16*VLOOKUP(E16,$B$7:$J$9,9,0)) -> 0 | O16: A
G17: =IF($B17="","",VLOOKUP(E17,$B$7:$J$9,IF(F17="SP6",4,IF(F17="SP10",5,6)),0)*IF(O17="",1,VLOOKUP(O17,$B$33:$E$36,4,0))) | H17: =IF($B17="","",D17*G17) | I17: =IF($B17="","",VLOOKUP(E17,$B$7:$J$9,7,0)) | J17: =IF($B17="","",H17*(1+I17)) | K17: =IF($B17="","",VLOOKUP(E17,$B$7:$J$9,8,0)) | L17: =IF($B17="","",ROUNDUP(J17/K17,0)) | M17: =IF($B17="","",L17*K17) | N17: =IF($B17="","",L17*VLOOKUP(E17,$B$7:$J$9,9,0))
G18: =IF($B18="","",VLOOKUP(E18,$B$7:$J$9,IF(F18="SP6",4,IF(F18="SP10",5,6)),0)*IF(O18="",1,VLOOKUP(O18,$B$33:$E$36,4,0))) | H18: =IF($B18="","",D18*G18) | I18: =IF($B18="","",VLOOKUP(E18,$B$7:$J$9,7,0)) | J18: =IF($B18="","",H18*(1+I18)) | K18: =IF($B18="","",VLOOKUP(E18,$B$7:$J$9,8,0)) | L18: =IF($B18="","",ROUNDUP(J18/K18,0)) | M18: =IF($B18="","",L18*K18) | N18: =IF($B18="","",L18*VLOOKUP(E18,$B$7:$J$9,9,0))
G19: =IF($B19="","",VLOOKUP(E19,$B$7:$J$9,IF(F19="SP6",4,IF(F19="SP10",5,6)),0)*IF(O19="",1,VLOOKUP(O19,$B$33:$E$36,4,0))) | H19: =IF($B19="","",D19*G19) | I19: =IF($B19="","",VLOOKUP(E19,$B$7:$J$9,7,0)) | J19: =IF($B19="","",H19*(1+I19)) | K19: =IF($B19="","",VLOOKUP(E19,$B$7:$J$9,8,0)) | L19: =IF($B19="","",ROUNDUP(J19/K19,0)) | M19: =IF($B19="","",L19*K19) | N19: =IF($B19="","",L19*VLOOKUP(E19,$B$7:$J$9,9,0))
G20: =IF($B20="","",VLOOKUP(E20,$B$7:$J$9,IF(F20="SP6",4,IF(F20="SP10",5,6)),0)*IF(O20="",1,VLOOKUP(O20,$B$33:$E$36,4,0))) | H20: =IF($B20="","",D20*G20) | I20: =IF($B20="","",VLOOKUP(E20,$B$7:$J$9,7,0)) | J20: =IF($B20="","",H20*(1+I20)) | K20: =IF($B20="","",VLOOKUP(E20,$B$7:$J$9,8,0)) | L20: =IF($B20="","",ROUNDUP(J20/K20,0)) | M20: =IF($B20="","",L20*K20) | N20: =IF($B20="","",L20*VLOOKUP(E20,$B$7:$J$9,9,0))
G21: =IF($B21="","",VLOOKUP(E21,$B$7:$J$9,IF(F21="SP6",4,IF(F21="SP10",5,6)),0)*IF(O21="",1,VLOOKUP(O21,$B$33:$E$36,4,0))) | H21: =IF($B21="","",D21*G21) | I21: =IF($B21="","",VLOOKUP(E21,$B$7:$J$9,7,0)) | J21: =IF($B21="","",H21*(1+I21)) | K21: =IF($B21="","",VLOOKUP(E21,$B$7:$J$9,8,0)) | L21: =IF($B21="","",ROUNDUP(J21/K21,0)) | M21: =IF($B21="","",L21*K21) | N21: =IF($B21="","",L21*VLOOKUP(E21,$B$7:$J$9,9,0))
G22: =IF($B22="","",VLOOKUP(E22,$B$7:$J$9,IF(F22="SP6",4,IF(F22="SP10",5,6)),0)*IF(O22="",1,VLOOKUP(O22,$B$33:$E$36,4,0))) | H22: =IF($B22="","",D22*G22) | I22: =IF($B22="","",VLOOKUP(E22,$B$7:$J$9,7,0)) | J22: =IF($B22="","",H22*(1+I22)) | K22: =IF($B22="","",VLOOKUP(E22,$B$7:$J$9,8,0)) | L22: =IF($B22="","",ROUNDUP(J22/K22,0)) | M22: =IF($B22="","",L22*K22) | N22: =IF($B22="","",L22*VLOOKUP(E22,$B$7:$J$9,9,0))
G23: =IF($B23="","",VLOOKUP(E23,$B$7:$J$9,IF(F23="SP6",4,IF(F23="SP10",5,6)),0)*IF(O23="",1,VLOOKUP(O23,$B$33:$E$36,4,0))) | H23: =IF($B23="","",D23*G23) | I23: =IF($B23="","",VLOOKUP(E23,$B$7:$J$9,7,0)) | J23: =IF($B23="","",H23*(1+I23)) | K23: =IF($B23="","",VLOOKUP(E23,$B$7:$J$9,8,0)) | L23: =IF($B23="","",ROUNDUP(J23/K23,0)) | M23: =IF($B23="","",L23*K23) | N23: =IF($B23="","",L23*VLOOKUP(E23,$B$7:$J$9,9,0))
G24: =IF($B24="","",VLOOKUP(E24,$B$7:$J$9,IF(F24="SP6",4,IF(F24="SP10",5,6)),0)*IF(O24="",1,VLOOKUP(O24,$B$33:$E$36,4,0))) | H24: =IF($B24="","",D24*G24) | I24: =IF($B24="","",VLOOKUP(E24,$B$7:$J$9,7,0)) | J24: =IF($B24="","",H24*(1+I24)) | K24: =IF($B24="","",VLOOKUP(E24,$B$7:$J$9,8,0)) | L24: =IF($B24="","",ROUNDUP(J24/K24,0)) | M24: =IF($B24="","",L24*K24) | N24: =IF($B24="","",L24*VLOOKUP(E24,$B$7:$J$9,9,0))
G25: =IF($B25="","",VLOOKUP(E25,$B$7:$J$9,IF(F25="SP6",4,IF(F25="SP10",5,6)),0)*IF(O25="",1,VLOOKUP(O25,$B$33:$E$36,4,0))) | H25: =IF($B25="","",D25*G25) | I25: =IF($B25="","",VLOOKUP(E25,$B$7:$J$9,7,0)) | J25: =IF($B25="","",H25*(1+I25)) | K25: =IF($B25="","",VLOOKUP(E25,$B$7:$J$9,8,0)) | L25: =IF($B25="","",ROUNDUP(J25/K25,0)) | M25: =IF($B25="","",L25*K25) | N25: =IF($B25="","",L25*VLOOKUP(E25,$B$7:$J$9,9,0))
